Workbook
Name budget2024: 'FFB Budget 2026 - 2 summary'!$C$5:$AG$52
Name budget2026: 'FFB Budget 2026 - 2 summary'!$C$5:$U$52
Name coupe: 'FFB Budget 2025'!$W$5:$Z$55
Name DARSO: 'DARSO GANG'!$A$7:$K$14
Name ERDI: 'YUDI GANG'!$A$7:$J$9
Name ffbbudgettwofive: 'FFB Budget 2026 - 2 summary'!$C$5:$AG$145
Name ffbbudgettwofive: 'FFB Budget 2025'!$C$5:$U$100
Name harvestinground: 'HARVESTING ROUND'!$B$3:$J$36
Name july: 'HARVESTING ROUND'!$N$3:$Y$37
Name manday: 'HARVESTING INTERVAL- JAN 26'!$C$5:$BG$76
Name NURAZANI: 'NU AZANI GANG'!$A$7:$J$12
Name october2024: 'HARVESTING INTERVAL- JAN 26'!$C$5:$BG$76
Name SERAN: 'SOFIO GANG'!$A$7:$J$12
Name WENDERLINUS: 'WENDERLINUS GANG '!$A$7:$J$14
Name year2022to23: 'Harvesting Round Record'!$B$9:$XFD$50
Name YUVENTUS: 'YUVENTUS UN GANG'!$A$7:$K$9

Sheet OVERALL BY GANG COMPARISON YTD2
A1: YIELD TO DATE OF CURRENT YEAR VS. PAST YEAR
D4: Budget (MT) | E4: YTD (MT) | F4: Budget (MT) | G4: YTD (MT) | H4: Actual Variance (MT) | I4: YTD MT / HA
B5: O/P | C5: Total HA | D5: 2026 | F5: 2025 | H5: 2026 vs 2025 | I5: 2026 | J5: 2025 | Z5: 2025 FFB BUDGET
B6: =B7 -> 2010 | C6: =SUM(C7:C18) -> 615.51 | D6: =SUM(D7:D18) -> 11520 | E6: =SUM(E7:E18) -> 723.12 | F6: =SUM(F7:F18) -> 12143 | G6: =SUM(G7:G18) -> 9294.3 | H6: =G6-E6 -> 8571.18 | I6: =E6/C6 -> 1.1748306 | J6: =G6/C6 -> 15.100161 | Z6: Jan | AA6: Feb | AB6: Mar | AC6: Apr | AD6: May | AE6: Jun | AF6: Jul | AG6: Aug | AH6: Sep | AI6: Oct | AJ6: Nov | AK6: Dec
A7: 1 | B7: =VLOOKUP(A7,coupe,3,FALSE) -> 2010 | C7: =VLOOKUP(A7,YUVENTUS,2,FALSE) -> 53.09 | D7: =VLOOKUP(A7,budget2026,19,FALSE) -> 1009 | E7: =VLOOKUP(A7,year2022to23,374,FALSE) -> 64.28 | F7: =VLOOKUP(A7,coupe,4,FALSE) -> 1064 | G7: =VLOOKUP(A7,year2022to23,313,FALSE) -> 909.79 | H7: =G7-E7 -> 845.51 | I7: =E7/C7 -> 1.2107742 | J7: =G7/C7 -> 17.136749 | Z7: =VLOOKUP(A7,ffbbudgettwofive,7,FALSE) -> 53.2 | AA7: =VLOOKUP(A7,ffbbudgettwofive,8,FALSE) -> 42.56 | AB7: =VLOOKUP(A7,ffbbudgettwofive,9,FALSE) -> 74.48 | AC7: =VLOOKUP(A7,ffbbudgettwofive,10,FALSE) -> 74.48 | AD7: =VLOOKUP(A7,ffbbudgettwofive,11,FALSE) -> 74.48 | AE7: =VLOOKUP(A7,ffbbudgettwofive,12,FALSE) -> 74.48 | AF7: =VLOOKUP(A7,ffbbudgettwofive,13,FALSE) -> 85 | AG7: =VLOOKUP(A7,ffbbudgettwofive,14,FALSE) -> 106 | AH7: =VLOOKUP(A7,ffbbudgettwofive,15,FALSE) -> 106 | AI7: =VLOOKUP(A7,ffbbudgettwofive,16,FALSE) -> 149 | AJ7: =VLOOKUP(A7,ffbbudgettwofive,17,FALSE) -> 117 | AK7: =VLOOKUP(A7,ffbbudgettwofive,18,FALSE) -> 106
A8: 2 | B8: =VLOOKUP(A8,coupe,3,FALSE) -> 2010 | C8: =VLOOKUP(A8,ERDI,2,FALSE) -> 60.27 | D8: =VLOOKUP(A8,budget2026,19,FALSE) -> 1151 | E8: =VLOOKUP(A8,year2022to23,374,FALSE) -> 89.97 | F8: =VLOOKUP(A8,coupe,4,FALSE) -> 1208 | G8: =VLOOKUP(A8,year2022to23,313,FALSE) -> 889.57 | H8: =G8-E8 -> 799.6 | I8: =E8/C8 -> 1.4927825 | J8: =G8/C8 -> 14.759748 | Z8: =VLOOKUP(A8,ffbbudgettwofive,7,FALSE) -> 60.4 | AA8: =VLOOKUP(A8,ffbbudgettwofive,8,FALSE) -> 48.32 | AB8: =VLOOKUP(A8,ffbbudgettwofive,9,FALSE) -> 84.56 | AC8: =VLOOKUP(A8,ffbbudgettwofive,10,FALSE) -> 84.56 | AD8: =VLOOKUP(A8,ffbbudgettwofive,11,FALSE) -> 84.56 | AE8: =VLOOKUP(A8,ffbbudgettwofive,12,FALSE) -> 84.56 | AF8: =VLOOKUP(A8,ffbbudgettwofive,13,FALSE) -> 97 | AG8: =VLOOKUP(A8,ffbbudgettwofive,14,FALSE) -> 121 | AH8: =VLOOKUP(A8,ffbbudgettwofive,15,FALSE) -> 121 | AI8: =VLOOKUP(A8,ffbbudgettwofive,16,FALSE) -> 169 | AJ8: =VLOOKUP(A8,ffbbudgettwofive,17,FALSE) -> 133 | AK8: =VLOOKUP(A8,ffbbudgettwofive,18,FALSE) -> 121
A9: 3 | B9: =VLOOKUP(A9,coupe,3,FALSE) -> 2010 | C9: =VLOOKUP(A9,YUVENTUS,2,FALSE) -> 69.04 | D9: =VLOOKUP(A9,budget2026,19,FALSE) -> 1312 | E9: =VLOOKUP(A9,year2022to23,374,FALSE) -> 86.26 | F9: =VLOOKUP(A9,coupe,4,FALSE) -> 1384 | G9: =VLOOKUP(A9,year2022to23,313,FALSE) -> 1085.75 | H9: =G9-E9 -> 999.49 | I9: =E9/C9 -> 1.2494206 | J9: =G9/C9 -> 15.72639 | Z9: =VLOOKUP(A9,ffbbudgettwofive,7,FALSE) -> 69.2 | AA9: =VLOOKUP(A9,ffbbudgettwofive,8,FALSE) -> 55.36 | AB9: =VLOOKUP(A9,ffbbudgettwofive,9,FALSE) -> 96.88 | AC9: =VLOOKUP(A9,ffbbudgettwofive,10,FALSE) -> 96.88 | AD9: =VLOOKUP(A9,ffbbudgettwofive,11,FALSE) -> 96.88 | AE9: =VLOOKUP(A9,ffbbudgettwofive,12,FALSE) -> 96.88 | AF9: =VLOOKUP(A9,ffbbudgettwofive,13,FALSE) -> 111 | AG9: =VLOOKUP(A9,ffbbudgettwofive,14,FALSE) -> 138 | AH9: =VLOOKUP(A9,ffbbudgettwofive,15,FALSE) -> 138 | AI9: =VLOOKUP(A9,ffbbudgettwofive,16,FALSE) -> 194 | AJ9: =VLOOKUP(A9,ffbbudgettwofive,17,FALSE) -> 152 | AK9: =VLOOKUP(A9,ffbbudgettwofive,18,FALSE) -> 138
A10: 4 | B10: =VLOOKUP(A10,coupe,3,FALSE) -> 2010 | C10: =VLOOKUP(A10,SERAN,2,FALSE) -> 70.51 | D10: =VLOOKUP(A10,budget2026,19,FALSE) -> 1341 | E10: =VLOOKUP(A10,year2022to23,374,FALSE) -> 70.91 | F10: =VLOOKUP(A10,coupe,4,FALSE) -> 1412 | G10: =VLOOKUP(A10,year2022to23,313,FALSE) -> 1063.57 | H10: =G10-E10 -> 992.66 | I10: =E10/C10 -> 1.005673 | J10: =G10/C10 -> 15.08396 | Z10: =VLOOKUP(A10,ffbbudgettwofive,7,FALSE) -> 70.6 | AA10: =VLOOKUP(A10,ffbbudgettwofive,8,FALSE) -> 56.48 | AB10: =VLOOKUP(A10,ffbbudgettwofive,9,FALSE) -> 98.84 | AC10: =VLOOKUP(A10,ffbbudgettwofive,10,FALSE) -> 98.84 | AD10: =VLOOKUP(A10,ffbbudgettwofive,11,FALSE) -> 98.84 | AE10: =VLOOKUP(A10,ffbbudgettwofive,12,FALSE) -> 98.84 | AF10: =VLOOKUP(A10,ffbbudgettwofive,13,FALSE) -> 113 | AG10: =VLOOKUP(A10,ffbbudgettwofive,14,FALSE) -> 141 | AH10: =VLOOKUP(A10,ffbbudgettwofive,15,FALSE) -> 141 | AI10: =VLOOKUP(A10,ffbbudgettwofive,16,FALSE) -> 198 | AJ10: =VLOOKUP(A10,ffbbudgettwofive,17,FALSE) -> 155 | AK10: =VLOOKUP(A10,ffbbudgettwofive,18,FALSE) -> 141
A11: 5 | B11: =VLOOKUP(A11,coupe,3,FALSE) -> 2010 | C11: =VLOOKUP(A11,SERAN,2,FALSE) -> 50.4 | D11: =VLOOKUP(A11,budget2026,19,FALSE) -> 958 | E11: =VLOOKUP(A11,year2022to23,374,FALSE) -> 38.89 | F11: =VLOOKUP(A11,coupe,4,FALSE) -> 1008 | G11: =VLOOKUP(A11,year2022to23,313,FALSE) -> 835.29 | H11: =G11-E11 -> 796.4 | I11: =E11/C11 -> 0.77162698 | J11: =G11/C11 -> 16.573214 | Z11: =VLOOKUP(A11,ffbbudgettwofive,7,FALSE) -> 50.4 | AA11: =VLOOKUP(A11,ffbbudgettwofive,8,FALSE) -> 40.32 | AB11: =VLOOKUP(A11,ffbbudgettwofive,9,FALSE) -> 70.56 | AC11: =VLOOKUP(A11,ffbbudgettwofive,10,FALSE) -> 70.56 | AD11: =VLOOKUP(A11,ffbbudgettwofive,11,FALSE) -> 70.56 | AE11: =VLOOKUP(A11,ffbbudgettwofive,12,FALSE) -> 70.56 | AF11: =VLOOKUP(A11,ffbbudgettwofive,13,FALSE) -> 81 | AG11: =VLOOKUP(A11,ffbbudgettwofive,14,FALSE) -> 101 | AH11: =VLOOKUP(A11,ffbbudgettwofive,15,FALSE) -> 101 | AI11: =VLOOKUP(A11,ffbbudgettwofive,16,FALSE) -> 141 | AJ11: =VLOOKUP(A11,ffbbudgettwofive,17,FALSE) -> 111 | AK11: =VLOOKUP(A11,ffbbudgettwofive,18,FALSE) -> 101
A12: 6 | B12: =VLOOKUP(A12,coupe,3,FALSE) -> 2010 | C12: =VLOOKUP(A12,SERAN,2,FALSE) -> 58.6 | D12: =VLOOKUP(A12,budget2026,19,FALSE) -> 1114 | E12: =VLOOKUP(A12,year2022to23,374,FALSE) -> 56.29 | F12: =VLOOKUP(A12,coupe,4,FALSE) -> 1172 | G12: =VLOOKUP(A12,year2022to23,313,FALSE) -> 961.24 | H12: =G12-E12 -> 904.95 | I12: =E12/C12 -> 0.9605802 | J12: =G12/C12 -> 16.403413 | Z12: =VLOOKUP(A12,ffbbudgettwofive,7,FALSE) -> 58.6 | AA12: =VLOOKUP(A12,ffbbudgettwofive,8,FALSE) -> 46.88 | AB12: =VLOOKUP(A12,ffbbudgettwofive,9,FALSE) -> 82.04 | AC12: =VLOOKUP(A12,ffbbudgettwofive,10,FALSE) -> 82.04 | AD12: =VLOOKUP(A12,ffbbudgettwofive,11,FALSE) -> 82.04 | AE12: =VLOOKUP(A12,ffbbudgettwofive,12,FALSE) -> 82.04 | AF12: =VLOOKUP(A12,ffbbudgettwofive,13,FALSE) -> 94 | AG12: =VLOOKUP(A12,ffbbudgettwofive,14,FALSE) -> 117 | AH12: =VLOOKUP(A12,ffbbudgettwofive,15,FALSE) -> 117 | AI12: =VLOOKUP(A12,ffbbudgettwofive,16,FALSE) -> 164 | AJ12: =VLOOKUP(A12,ffbbudgettwofive,17,FALSE) -> 129 | AK12: =VLOOKUP(A12,ffbbudgettwofive,18,FALSE) -> 117
A13: 7 | B13: =VLOOKUP(A13,coupe,3,FALSE) -> 2010 | C13: =VLOOKUP(A13,SERAN,2,FALSE) -> 23.6 | D13: =VLOOKUP(A13,budget2026,19,FALSE) -> 381 | E13: =VLOOKUP(A13,year2022to23,374,FALSE) -> 24.72 | F13: =VLOOKUP(A13,coupe,4,FALSE) -> 401 | G13: =VLOOKUP(A13,year2022to23,313,FALSE) -> 334.61 | H13: =G13-E13 -> 309.89 | I13: =E13/C13 -> 1.0474576 | J13: =G13/C13 -> 14.17839 | Z13: =VLOOKUP(A13,ffbbudgettwofive,7,FALSE) -> 20.05 | AA13: =VLOOKUP(A13,ffbbudgettwofive,8,FALSE) -> 16.04 | AB13: =VLOOKUP(A13,ffbbudgettwofive,9,FALSE) -> 28.07 | AC13: =VLOOKUP(A13,ffbbudgettwofive,10,FALSE) -> 28.07 | AD13: =VLOOKUP(A13,ffbbudgettwofive,11,FALSE) -> 28.07 | AE13: =VLOOKUP(A13,ffbbudgettwofive,12,FALSE) -> 28.07 | AF13: =VLOOKUP(A13,ffbbudgettwofive,13,FALSE) -> 32 | AG13: =VLOOKUP(A13,ffbbudgettwofive,14,FALSE) -> 40 | AH13: =VLOOKUP(A13,ffbbudgettwofive,15,FALSE) -> 40 | AI13: =VLOOKUP(A13,ffbbudgettwofive,16,FALSE) -> 56 | AJ13: =VLOOKUP(A13,ffbbudgettwofive,17,FALSE) -> 44 | AK13: =VLOOKUP(A13,ffbbudgettwofive,18,FALSE) -> 40
A14: 8 | B14: =VLOOKUP(A14,coupe,3,FALSE) -> 2010 | C14: =VLOOKUP(A14,NURAZANI,2,FALSE) -> 61.6 | D14: =VLOOKUP(A14,budget2026,19,FALSE) -> 1155 | E14: =VLOOKUP(A14,year2022to23,374,FALSE) -> 89.5 | F14: =VLOOKUP(A14,coupe,4,FALSE) -> 1232 | G14: =VLOOKUP(A14,year2022to23,313,FALSE) -> 906.12 | H14: =G14-E14 -> 816.62 | I14: =E14/C14 -> 1.4529221 | J14: =G14/C14 -> 14.70974 | Z14: =VLOOKUP(A14,ffbbudgettwofive,7,FALSE) -> 61.6 | AA14: =VLOOKUP(A14,ffbbudgettwofive,8,FALSE) -> 49.28 | AB14: =VLOOKUP(A14,ffbbudgettwofive,9,FALSE) -> 86.24 | AC14: =VLOOKUP(A14,ffbbudgettwofive,10,FALSE) -> 86.24 | AD14: =VLOOKUP(A14,ffbbudgettwofive,11,FALSE) -> 86.24 | AE14: =VLOOKUP(A14,ffbbudgettwofive,12,FALSE) -> 86.24 | AF14: =VLOOKUP(A14,ffbbudgettwofive,13,FALSE) -> 99 | AG14: =VLOOKUP(A14,ffbbudgettwofive,14,FALSE) -> 123 | AH14: =VLOOKUP(A14,ffbbudgettwofive,15,FALSE) -> 123 | AI14: =VLOOKUP(A14,ffbbudgettwofive,16,FALSE) -> 172 | AJ14: =VLOOKUP(A14,ffbbudgettwofive,17,FALSE) -> 136 | AK14: =VLOOKUP(A14,ffbbudgettwofive,18,FALSE) -> 123
A15: 9 | B15: =VLOOKUP(A15,coupe,3,FALSE) -> 2010 | C15: =VLOOKUP(A15,NURAZANI,2,FALSE) -> 38.3 | D15: =VLOOKUP(A15,budget2026,19,FALSE) -> 658 | E15: =VLOOKUP(A15,year2022to23,374,FALSE) -> 45.99 | F15: =VLOOKUP(A15,coupe,4,FALSE) -> 689 | G15: =VLOOKUP(A15,year2022to23,313,FALSE) -> 486.12 | H15: =G15-E15 -> 440.13 | I15: =E15/C15 -> 1.2007833 | J15: =G15/C15 -> 12.692428 | Z15: =VLOOKUP(A15,ffbbudgettwofive,7,FALSE) -> 34.45 | AA15: =VLOOKUP(A15,ffbbudgettwofive,8,FALSE) -> 27.56 | AB15: =VLOOKUP(A15,ffbbudgettwofive,9,FALSE) -> 48.23 | AC15: =VLOOKUP(A15,ffbbudgettwofive,10,FALSE) -> 48.23 | AD15: =VLOOKUP(A15,ffbbudgettwofive,11,FALSE) -> 48.23 | AE15: =VLOOKUP(A15,ffbbudgettwofive,12,FALSE) -> 48.23 | AF15: =VLOOKUP(A15,ffbbudgettwofive,13,FALSE) -> 55 | AG15: =VLOOKUP(A15,ffbbudgettwofive,14,FALSE) -> 69 | AH15: =VLOOKUP(A15,ffbbudgettwofive,15,FALSE) -> 69 | AI15: =VLOOKUP(A15,ffbbudgettwofive,16,FALSE) -> 97 | AJ15: =VLOOKUP(A15,ffbbudgettwofive,17,FALSE) -> 76 | AK15: =VLOOKUP(A15,ffbbudgettwofive,18,FALSE) -> 69
A16: 11 | B16: =VLOOKUP(A16,coupe,3,FALSE) -> 2010 | C16: =VLOOKUP(A16,ERDI,2,FALSE) -> 44.5 | D16: =VLOOKUP(A16,budget2026,19,FALSE) -> 804 | E16: =VLOOKUP(A16,year2022to23,374,FALSE) -> 50.57 | F16: =VLOOKUP(A16,coupe,4,FALSE) -> 846 | G16: =VLOOKUP(A16,year2022to23,313,FALSE) -> 529.89 | H16: =G16-E16 -> 479.32 | I16: =E16/C16 -> 1.1364045 | J16: =G16/C16 -> 11.90764 | Z16: =VLOOKUP(A16,ffbbudgettwofive,7,FALSE) -> 42.3 | AA16: =VLOOKUP(A16,ffbbudgettwofive,8,FALSE) -> 33.84 | AB16: =VLOOKUP(A16,ffbbudgettwofive,9,FALSE) -> 59.22 | AC16: =VLOOKUP(A16,ffbbudgettwofive,10,FALSE) -> 59.22 | AD16: =VLOOKUP(A16,ffbbudgettwofive,11,FALSE) -> 59.22 | AE16: =VLOOKUP(A16,ffbbudgettwofive,12,FALSE) -> 59.22 | AF16: =VLOOKUP(A16,ffbbudgettwofive,13,FALSE) -> 68 | AG16: =VLOOKUP(A16,ffbbudgettwofive,14,FALSE) -> 85 | AH16: =VLOOKUP(A16,ffbbudgettwofive,15,FALSE) -> 85 | AI16: =VLOOKUP(A16,ffbbudgettwofive,16,FALSE) -> 118 | AJ16: =VLOOKUP(A16,ffbbudgettwofive,17,FALSE) -> 93 | AK16: =VLOOKUP(A16,ffbbudgettwofive,18,FALSE) -> 85
A17: 12 | B17: =VLOOKUP(A17,coupe,3,FALSE) -> 2010 | C17: =VLOOKUP(A17,NURAZANI,2,FALSE) -> 71 | D17: =VLOOKUP(A17,budget2026,19,FALSE) -> 1348 | E17: =VLOOKUP(A17,year2022to23,374,FALSE) -> 84.58 | F17: =VLOOKUP(A17,coupe,4,FALSE) -> 1420 | G17: =VLOOKUP(A17,year2022to23,313,FALSE) -> 1000.74 | H17: =G17-E17 -> 916.16 | I17: =E17/C17 -> 1.1912676 | J17: =G17/C17 -> 14.09493 | Z17: =VLOOKUP(A17,ffbbudgettwofive,7,FALSE) -> 71 | AA17: =VLOOKUP(A17,ffbbudgettwofive,8,FALSE) -> 56.8 | AB17: =VLOOKUP(A17,ffbbudgettwofive,9,FALSE) -> 99.4 | AC17: =VLOOKUP(A17,ffbbudgettwofive,10,FALSE) -> 99.4 | AD17: =VLOOKUP(A17,ffbbudgettwofive,11,FALSE) -> 99.4 | AE17: =VLOOKUP(A17,ffbbudgettwofive,12,FALSE) -> 99.4 | AF17: =VLOOKUP(A17,ffbbudgettwofive,13,FALSE) -> 114 | AG17: =VLOOKUP(A17,ffbbudgettwofive,14,FALSE) -> 142 | AH17: =VLOOKUP(A17,ffbbudgettwofive,15,FALSE) -> 142 | AI17: =VLOOKUP(A17,ffbbudgettwofive,16,FALSE) -> 199 | AJ17: =VLOOKUP(A17,ffbbudgettwofive,17,FALSE) -> 156 | AK17: =VLOOKUP(A17,ffbbudgettwofive,18,FALSE) -> 142
A18: 23 | B18: =VLOOKUP(A18,coupe,3,FALSE) -> 2010 | C18: =VLOOKUP(A18,SERAN,2,FALSE) -> 14.6 | D18: =VLOOKUP(A18,budget2026,19,FALSE) -> 289 | E18: =VLOOKUP(A18,year2022to23,374,FALSE) -> 21.16 | F18: =VLOOKUP(A18,coupe,4,FALSE) -> 307 | G18: =VLOOKUP(A18,year2022to23,313,FALSE) -> 291.61 | H18: =G18-E18 -> 270.45 | I18: =E18/C18 -> 1.4493151 | J18: =G18/C18 -> 19.973288 | Z18: =VLOOKUP(A18,ffbbudgettwofive,7,FALSE) -> 15.35 | AA18: =VLOOKUP(A18,ffbbudgettwofive,8,FALSE) -> 12.28 | AB18: =VLOOKUP(A18,ffbbudgettwofive,9,FALSE) -> 21.49 | AC18: =VLOOKUP(A18,ffbbudgettwofive,10,FALSE) -> 21.49 | AD18: =VLOOKUP(A18,ffbbudgettwofive,11,FALSE) -> 21.49 | AE18: =VLOOKUP(A18,ffbbudgettwofive,12,FALSE) -> 21.49 | AF18: =VLOOKUP(A18,ffbbudgettwofive,13,FALSE) -> 25 | AG18: =VLOOKUP(A18,ffbbudgettwofive,14,FALSE) -> 31 | AH18: =VLOOKUP(A18,ffbbudgettwofive,15,FALSE) -> 31 | AI18: =VLOOKUP(A18,ffbbudgettwofive,16,FALSE) -> 43 | AJ18: =VLOOKUP(A18,ffbbudgettwofive,17,FALSE) -> 34 | AK18: =VLOOKUP(A18,ffbbudgettwofive,18,FALSE) -> 31
B20: =B21 -> 2011 | C20: =SUM(C21:C27) -> 309.66 | D20: =SUM(D21:D27) -> 6205 | E20: =SUM(E21:E27) -> 442.61 | F20: =SUM(F21:F27) -> 6528 | G20: =SUM(G21:G27) -> 5287.5 | H20: =G20-E20 -> 4844.89 | I20: =E20/C20 -> 1.4293419 | J20: =G20/C20 -> 17.075179 | Z20: Jan | AA20: Feb | AB20: Mar | AC20: Apr | AD20: May | AE20: Jun | AF20: Jul | AG20: Aug | AH20: Sep | AI20: Oct | AJ20: Nov | AK20: Dec
A21: 10 | B21: =VLOOKUP(A21,coupe,3,FALSE) -> 2011 | C21: =VLOOKUP(A21,NURAZANI,2,FALSE) -> 19.1 | D21: =VLOOKUP(A21,budget2026,19,FALSE) -> 343 | E21: =VLOOKUP(A21,year2022to23,374,FALSE) -> 28.48 | F21: =VLOOKUP(A21,coupe,4,FALSE) -> 363 | G21: =VLOOKUP(A21,year2022to23,313,FALSE) -> 259.04 | H21: =G21-E21 -> 230.56 | I21: =E21/C21 -> 1.4910995 | J21: =G21/C21 -> 13.562304 | Z21: =VLOOKUP(A21,ffbbudgettwofive,7,FALSE) -> 18.15 | AA21: =VLOOKUP(A21,ffbbudgettwofive,8,FALSE) -> 14.52 | AB21: =VLOOKUP(A21,ffbbudgettwofive,9,FALSE) -> 25.41 | AC21: =VLOOKUP(A21,ffbbudgettwofive,10,FALSE) -> 25.41 | AD21: =VLOOKUP(A21,ffbbudgettwofive,11,FALSE) -> 25.41 | AE21: =VLOOKUP(A21,ffbbudgettwofive,12,FALSE) -> 25.41 | AF21: =VLOOKUP(A21,ffbbudgettwofive,13,FALSE) -> 29 | AG21: =VLOOKUP(A21,ffbbudgettwofive,14,FALSE) -> 36 | AH21: =VLOOKUP(A21,ffbbudgettwofive,15,FALSE) -> 36 | AI21: =VLOOKUP(A21,ffbbudgettwofive,16,FALSE) -> 51 | AJ21: =VLOOKUP(A21,ffbbudgettwofive,17,FALSE) -> 40 | AK21: =VLOOKUP(A21,ffbbudgettwofive,18,FALSE) -> 36
A22: 13 | B22: =VLOOKUP(A22,coupe,3,FALSE) -> 2011 | C22: =VLOOKUP(A22,NURAZANI,2,FALSE) -> 60.8 | D22: =VLOOKUP(A22,budget2026,19,FALSE) -> 1272 | E22: =VLOOKUP(A22,year2022to23,374,FALSE) -> 89.17 | F22: =VLOOKUP(A22,coupe,4,FALSE) -> 1338 | G22: =VLOOKUP(A22,year2022to23,313,FALSE) -> 1038.9 | H22: =G22-E22 -> 949.73 | I22: =E22/C22 -> 1.4666118 | J22: =G22/C22 -> 17.087171 | Z22: =VLOOKUP(A22,ffbbudgettwofive,7,FALSE) -> 66.9 | AA22: =VLOOKUP(A22,ffbbudgettwofive,8,FALSE) -> 53.52 | AB22: =VLOOKUP(A22,ffbbudgettwofive,9,FALSE) -> 93.66 | AC22: =VLOOKUP(A22,ffbbudgettwofive,10,FALSE) -> 93.66 | AD22: =VLOOKUP(A22,ffbbudgettwofive,11,FALSE) -> 93.66 | AE22: =VLOOKUP(A22,ffbbudgettwofive,12,FALSE) -> 93.66 | AF22: =VLOOKUP(A22,ffbbudgettwofive,13,FALSE) -> 107 | AG22: =VLOOKUP(A22,ffbbudgettwofive,14,FALSE) -> 134 | AH22: =VLOOKUP(A22,ffbbudgettwofive,15,FALSE) -> 134 | AI22: =VLOOKUP(A22,ffbbudgettwofive,16,FALSE) -> 187 | AJ22: =VLOOKUP(A22,ffbbudgettwofive,17,FALSE) -> 147 | AK22: =VLOOKUP(A22,ffbbudgettwofive,18,FALSE) -> 134
A23: 14 | B23: =VLOOKUP(A23,coupe,3,FALSE) -> 2011 | C23: =VLOOKUP(A23,YUVENTUS,2,FALSE) -> 41.6 | D23: =VLOOKUP(A23,budget2026,19,FALSE) -> 830 | E23: =VLOOKUP(A23,year2022to23,374,FALSE) -> 62.28 | F23: =VLOOKUP(A23,coupe,4,FALSE) -> 874 | G23: =VLOOKUP(A23,year2022to23,313,FALSE) -> 714.03 | H23: =G23-E23 -> 651.75 | I23: =E23/C23 -> 1.4971154 | J23: =G23/C23 -> 17.164183 | Z23: =VLOOKUP(A23,ffbbudgettwofive,7,FALSE) -> 43.7 | AA23: =VLOOKUP(A23,ffbbudgettwofive,8,FALSE) -> 34.96 | AB23: =VLOOKUP(A23,ffbbudgettwofive,9,FALSE) -> 61.18 | AC23: =VLOOKUP(A23,ffbbudgettwofive,10,FALSE) -> 61.18 | AD23: =VLOOKUP(A23,ffbbudgettwofive,11,FALSE) -> 61.18 | AE23: =VLOOKUP(A23,ffbbudgettwofive,12,FALSE) -> 61.18 | AF23: =VLOOKUP(A23,ffbbudgettwofive,13,FALSE) -> 70 | AG23: =VLOOKUP(A23,ffbbudgettwofive,14,FALSE) -> 87 | AH23: =VLOOKUP(A23,ffbbudgettwofive,15,FALSE) -> 87 | AI23: =VLOOKUP(A23,ffbbudgettwofive,16,FALSE) -> 122 | AJ23: =VLOOKUP(A23,ffbbudgettwofive,17,FALSE) -> 96 | AK23: =VLOOKUP(A23,ffbbudgettwofive,18,FALSE) -> 87
A24: 15 | B24: =VLOOKUP(A24,coupe,3,FALSE) -> 2011 | C24: =VLOOKUP(A24,DARSO,2,FALSE) -> 49.17 | D24: =VLOOKUP(A24,budget2026,19,FALSE) -> 939 | E24: =VLOOKUP(A24,year2022to23,374,FALSE) -> 63.96 | F24: =VLOOKUP(A24,coupe,4,FALSE) -> 986 | G24: =VLOOKUP(A24,year2022to23,313,FALSE) -> 776.89 | H24: =G24-E24 -> 712.93 | I24: =E24/C24 -> 1.3007932 | J24: =G24/C24 -> 15.800081 | Z24: =VLOOKUP(A24,ffbbudgettwofive,7,FALSE) -> 49.3 | AA24: =VLOOKUP(A24,ffbbudgettwofive,8,FALSE) -> 39.44 | AB24: =VLOOKUP(A24,ffbbudgettwofive,9,FALSE) -> 69.02 | AC24: =VLOOKUP(A24,ffbbudgettwofive,10,FALSE) -> 69.02 | AD24: =VLOOKUP(A24,ffbbudgettwofive,11,FALSE) -> 69.02 | AE24: =VLOOKUP(A24,ffbbudgettwofive,12,FALSE) -> 69.02 | AF24: =VLOOKUP(A24,ffbbudgettwofive,13,FALSE) -> 79 | AG24: =VLOOKUP(A24,ffbbudgettwofive,14,FALSE) -> 99 | AH24: =VLOOKUP(A24,ffbbudgettwofive,15,FALSE) -> 99 | AI24: =VLOOKUP(A24,ffbbudgettwofive,16,FALSE) -> 138 | AJ24: =VLOOKUP(A24,ffbbudgettwofive,17,FALSE) -> 108 | AK24: =VLOOKUP(A24,ffbbudgettwofive,18,FALSE) -> 99
A25: 16 | B25: =VLOOKUP(A25,coupe,3,FALSE) -> 2011 | C25: =VLOOKUP(A25,DARSO,2,FALSE) -> 52.61 | D25: =VLOOKUP(A25,budget2026,19,FALSE) -> 1008 | E25: =VLOOKUP(A25,year2022to23,374,FALSE) -> 80.23 | F25: =VLOOKUP(A25,coupe,4,FALSE) -> 1064 | G25: =VLOOKUP(A25,year2022to23,313,FALSE) -> 900.68 | H25: =G25-E25 -> 820.45 | I25: =E25/C25 -> 1.5249952 | J25: =G25/C25 -> 17.119939 | Z25: =VLOOKUP(A25,ffbbudgettwofive,7,FALSE) -> 53.2 | AA25: =VLOOKUP(A25,ffbbudgettwofive,8,FALSE) -> 42.56 | AB25: =VLOOKUP(A25,ffbbudgettwofive,9,FALSE) -> 74.48 | AC25: =VLOOKUP(A25,ffbbudgettwofive,10,FALSE) -> 74.48 | AD25: =VLOOKUP(A25,ffbbudgettwofive,11,FALSE) -> 74.48 | AE25: =VLOOKUP(A25,ffbbudgettwofive,12,FALSE) -> 74.48 | AF25: =VLOOKUP(A25,ffbbudgettwofive,13,FALSE) -> 85 | AG25: =VLOOKUP(A25,ffbbudgettwofive,14,FALSE) -> 106 | AH25: =VLOOKUP(A25,ffbbudgettwofive,15,FALSE) -> 106 | AI25: =VLOOKUP(A25,ffbbudgettwofive,16,FALSE) -> 149 | AJ25: =VLOOKUP(A25,ffbbudgettwofive,17,FALSE) -> 117 | AK25: =VLOOKUP(A25,ffbbudgettwofive,18,FALSE) -> 106
A26: 17 | B26: =VLOOKUP(A26,coupe,3,FALSE) -> 2011 | C26: =VLOOKUP(A26,DARSO,2,FALSE) -> 45.58 | D26: =VLOOKUP(A26,budget2026,19,FALSE) -> 957 | E26: =VLOOKUP(A26,year2022to23,374,FALSE) -> 58.15 | F26: =VLOOKUP(A26,coupe,4,FALSE) -> 1005 | G26: =VLOOKUP(A26,year2022to23,313,FALSE) -> 797.25 | H26: =G26-E26 -> 739.1 | I26: =E26/C26 -> 1.2757789 | J26: =G26/C26 -> 17.491224 | Z26: =VLOOKUP(A26,ffbbudgettwofive,7,FALSE) -> 50.25 | AA26: =VLOOKUP(A26,ffbbudgettwofive,8,FALSE) -> 40.2 | AB26: =VLOOKUP(A26,ffbbudgettwofive,9,FALSE) -> 70.35 | AC26: =VLOOKUP(A26,ffbbudgettwofive,10,FALSE) -> 70.35 | AD26: =VLOOKUP(A26,ffbbudgettwofive,11,FALSE) -> 70.35 | AE26: =VLOOKUP(A26,ffbbudgettwofive,12,FALSE) -> 70.35 | AF26: =VLOOKUP(A26,ffbbudgettwofive,13,FALSE) -> 80 | AG26: =VLOOKUP(A26,ffbbudgettwofive,14,FALSE) -> 101 | AH26: =VLOOKUP(A26,ffbbudgettwofive,15,FALSE) -> 101 | AI26: =VLOOKUP(A26,ffbbudgettwofive,16,FALSE) -> 141 | AJ26: =VLOOKUP(A26,ffbbudgettwofive,17,FALSE) -> 111 | AK26: =VLOOKUP(A26,ffbbudgettwofive,18,FALSE) -> 101
A27: 18 | B27: =VLOOKUP(A27,coupe,3,FALSE) -> 2011 | C27: =VLOOKUP(A27,NURAZANI,2,FALSE) -> 40.8 | D27: =VLOOKUP(A27,budget2026,19,FALSE) -> 856 | E27: =VLOOKUP(A27,year2022to23,374,FALSE) -> 60.34 | F27: =VLOOKUP(A27,coupe,4,FALSE) -> 898 | G27: =VLOOKUP(A27,year2022to23,313,FALSE) -> 800.71 | H27: =G27-E27 -> 740.37 | I27: =E27/C27 -> 1.4789216 | J27: =G27/C27 -> 19.625245 | Z27: =VLOOKUP(A27,ffbbudgettwofive,7,FALSE) -> 44.9 | AA27: =VLOOKUP(A27,ffbbudgettwofive,8,FALSE) -> 35.92 | AB27: =VLOOKUP(A27,ffbbudgettwofive,9,FALSE) -> 62.86 | AC27: =VLOOKUP(A27,ffbbudgettwofive,10,FALSE) -> 62.86 | AD27: =VLOOKUP(A27,ffbbudgettwofive,11,FALSE) -> 62.86 | AE27: =VLOOKUP(A27,ffbbudgettwofive,12,FALSE) -> 62.86 | AF27: =VLOOKUP(A27,ffbbudgettwofive,13,FALSE) -> 72 | AG27: =VLOOKUP(A27,ffbbudgettwofive,14,FALSE) -> 90 | AH27: =VLOOKUP(A27,ffbbudgettwofive,15,FALSE) -> 90 | AI27: =VLOOKUP(A27,ffbbudgettwofive,16,FALSE) -> 126 | AJ27: =VLOOKUP(A27,ffbbudgettwofive,17,FALSE) -> 99 | AK27: =VLOOKUP(A27,ffbbudgettwofive,18,FALSE) -> 90
B29: =B30 -> 2012 | C29: =SUM(C30:C34) -> 280.92 | D29: =SUM(D30:D34) -> 5627 | E29: =SUM(E30:E34) -> 328.35 | F29: =SUM(F30:F34) -> 5931 | G29: =SUM(G30:G34) -> 4872.33 | H29: =G29-E29 -> 4543.98 | I29: =E29/C29 -> 1.1688381 | J29: =G29/C29 -> 17.344191 | Z29: Jan | AA29: Feb | AB29: Mar | AC29: Apr | AD29: May | AE29: Jun | AF29: Jul | AG29: Aug | AH29: Sep | AI29: Oct | AJ29: Nov | AK29: Dec
A30: 19 | B30: =VLOOKUP(A30,coupe,3,FALSE) -> 2012 | C30: =VLOOKUP(A30,DARSO,2,FALSE) -> 50.6 | D30: =VLOOKUP(A30,budget2026,19,FALSE) -> 1008 | E30: =VLOOKUP(A30,year2022to23,374,FALSE) -> 44.28 | F30: =VLOOKUP(A30,coupe,4,FALSE) -> 1063 | G30: =VLOOKUP(A30,year2022to23,313,FALSE) -> 866 | H30: =G30-E30 -> 821.72 | I30: =E30/C30 -> 0.87509881 | J30: =G30/C30 -> 17.114625 | Z30: =VLOOKUP(A30,ffbbudgettwofive,7,FALSE) -> 53.15 | AA30: =VLOOKUP(A30,ffbbudgettwofive,8,FALSE) -> 42.52 | AB30: =VLOOKUP(A30,ffbbudgettwofive,9,FALSE) -> 74.41 | AC30: =VLOOKUP(A30,ffbbudgettwofive,10,FALSE) -> 74.41 | AD30: =VLOOKUP(A30,ffbbudgettwofive,11,FALSE) -> 74.41 | AE30: =VLOOKUP(A30,ffbbudgettwofive,12,FALSE) -> 74.41 | AF30: =VLOOKUP(A30,ffbbudgettwofive,13,FALSE) -> 85 | AG30: =VLOOKUP(A30,ffbbudgettwofive,14,FALSE) -> 106 | AH30: =VLOOKUP(A30,ffbbudgettwofive,15,FALSE) -> 106 | AI30: =VLOOKUP(A30,ffbbudgettwofive,16,FALSE) -> 149 | AJ30: =VLOOKUP(A30,ffbbudgettwofive,17,FALSE) -> 117 | AK30: =VLOOKUP(A30,ffbbudgettwofive,18,FALSE) -> 106
A31: 20 | B31: =VLOOKUP(A31,coupe,3,FALSE) -> 2012 | C31: =VLOOKUP(A31,DARSO,2,FALSE) -> 61.98 | D31: =VLOOKUP(A31,budget2026,19,FALSE) -> 1236 | E31: =VLOOKUP(A31,year2022to23,374,FALSE) -> 49.23 | F31: =VLOOKUP(A31,coupe,4,FALSE) -> 1304 | G31: =VLOOKUP(A31,year2022to23,313,FALSE) -> 1028.6 | H31: =G31-E31 -> 979.37 | I31: =E31/C31 -> 0.79428848 | J31: =G31/C31 -> 16.595676 | Z31: =VLOOKUP(A31,ffbbudgettwofive,7,FALSE) -> 65.2 | AA31: =VLOOKUP(A31,ffbbudgettwofive,8,FALSE) -> 52.16 | AB31: =VLOOKUP(A31,ffbbudgettwofive,9,FALSE) -> 91.28 | AC31: =VLOOKUP(A31,ffbbudgettwofive,10,FALSE) -> 91.28 | AD31: =VLOOKUP(A31,ffbbudgettwofive,11,FALSE) -> 91.28 | AE31: =VLOOKUP(A31,ffbbudgettwofive,12,FALSE) -> 91.28 | AF31: =VLOOKUP(A31,ffbbudgettwofive,13,FALSE) -> 104 | AG31: =VLOOKUP(A31,ffbbudgettwofive,14,FALSE) -> 130 | AH31: =VLOOKUP(A31,ffbbudgettwofive,15,FALSE) -> 130 | AI31: =VLOOKUP(A31,ffbbudgettwofive,16,FALSE) -> 183 | AJ31: =VLOOKUP(A31,ffbbudgettwofive,17,FALSE) -> 143 | AK31: =VLOOKUP(A31,ffbbudgettwofive,18,FALSE) -> 130
A32: 21 | B32: =VLOOKUP(A32,coupe,3,FALSE) -> 2012 | C32: =VLOOKUP(A32,DARSO,2,FALSE) -> 71.59 | D32: =VLOOKUP(A32,budget2026,19,FALSE) -> 1576 | E32: =VLOOKUP(A32,year2022to23,374,FALSE) -> 93.8 | F32: =VLOOKUP(A32,coupe,4,FALSE) -> 1661 | G32: =VLOOKUP(A32,year2022to23,313,FALSE) -> 1324.41 | H32: =G32-E32 -> 1230.61 | I32: =E32/C32 -> 1.3102389 | J32: =G32/C32 -> 18.49993 | Z32: =VLOOKUP(A32,ffbbudgettwofive,7,FALSE) -> 83.05 | AA32: =VLOOKUP(A32,ffbbudgettwofive,8,FALSE) -> 66.44 | AB32: =VLOOKUP(A32,ffbbudgettwofive,9,FALSE) -> 116.27 | AC32: =VLOOKUP(A32,ffbbudgettwofive,10,FALSE) -> 116.27 | AD32: =VLOOKUP(A32,ffbbudgettwofive,11,FALSE) -> 116.27 | AE32: =VLOOKUP(A32,ffbbudgettwofive,12,FALSE) -> 116.27 | AF32: =VLOOKUP(A32,ffbbudgettwofive,13,FALSE) -> 133 | AG32: =VLOOKUP(A32,ffbbudgettwofive,14,FALSE) -> 166 | AH32: =VLOOKUP(A32,ffbbudgettwofive,15,FALSE) -> 166 | AI32: =VLOOKUP(A32,ffbbudgettwofive,16,FALSE) -> 232 | AJ32: =VLOOKUP(A32,ffbbudgettwofive,17,FALSE) -> 183 | AK32: =VLOOKUP(A32,ffbbudgettwofive,18,FALSE) -> 166
A33: 22 | B33: =VLOOKUP(A33,coupe,3,FALSE) -> 2012 | C33: =VLOOKUP(A33,DARSO,2,FALSE) -> 52.08 | D33: =VLOOKUP(A33,budget2026,19,FALSE) -> 1046 | E33: =VLOOKUP(A33,year2022to23,374,FALSE) -> 84.74 | F33: =VLOOKUP(A33,coupe,4,FALSE) -> 1098 | G33: =VLOOKUP(A33,year2022to23,313,FALSE) -> 845.84 | H33: =G33-E33 -> 761.1 | I33: =E33/C33 -> 1.6271121 | J33: =G33/C33 -> 16.241167 | Z33: =VLOOKUP(A33,ffbbudgettwofive,7,FALSE) -> 54.9 | AA33: =VLOOKUP(A33,ffbbudgettwofive,8,FALSE) -> 43.92 | AB33: =VLOOKUP(A33,ffbbudgettwofive,9,FALSE) -> 76.86 | AC33: =VLOOKUP(A33,ffbbudgettwofive,10,FALSE) -> 76.86 | AD33: =VLOOKUP(A33,ffbbudgettwofive,11,FALSE) -> 76.86 | AE33: =VLOOKUP(A33,ffbbudgettwofive,12,FALSE) -> 76.86 | AF33: =VLOOKUP(A33,ffbbudgettwofive,13,FALSE) -> 88 | AG33: =VLOOKUP(A33,ffbbudgettwofive,14,FALSE) -> 110 | AH33: =VLOOKUP(A33,ffbbudgettwofive,15,FALSE) -> 110 | AI33: =VLOOKUP(A33,ffbbudgettwofive,16,FALSE) -> 154 | AJ33: =VLOOKUP(A33,ffbbudgettwofive,17,FALSE) -> 121 | AK33: =VLOOKUP(A33,ffbbudgettwofive,18,FALSE) -> 110
A34: 24 | B34: =VLOOKUP(A34,coupe,3,FALSE) -> 2012 | C34: =VLOOKUP(A34,SERAN,2,FALSE) -> 44.67 | D34: =VLOOKUP(A34,budget2026,19,FALSE) -> 761 | E34: =VLOOKUP(A34,year2022to23,374,FALSE) -> 56.3 | F34: =VLOOKUP(A34,coupe,4,FALSE) -> 805 | G34: =VLOOKUP(A34,year2022to23,313,FALSE) -> 807.48 | H34: =G34-E34 -> 751.18 | I34: =E34/C34 -> 1.2603537 | J34: =G34/C34 -> 18.076561 | Z34: =VLOOKUP(A34,ffbbudgettwofive,7,FALSE) -> 40.25 | AA34: =VLOOKUP(A34,ffbbudgettwofive,8,FALSE) -> 32.2 | AB34: =VLOOKUP(A34,ffbbudgettwofive,9,FALSE) -> 56.35 | AC34: =VLOOKUP(A34,ffbbudgettwofive,10,FALSE) -> 56.35 | AD34: =VLOOKUP(A34,ffbbudgettwofive,11,FALSE) -> 56.35 | AE34: =VLOOKUP(A34,ffbbudgettwofive,12,FALSE) -> 56.35 | AF34: =VLOOKUP(A34,ffbbudgettwofive,13,FALSE) -> 64 | AG34: =VLOOKUP(A34,ffbbudgettwofive,14,FALSE) -> 81 | AH34: =VLOOKUP(A34,ffbbudgettwofive,15,FALSE) -> 81 | AI34: =VLOOKUP(A34,ffbbudgettwofive,16,FALSE) -> 113 | AJ34: =VLOOKUP(A34,ffbbudgettwofive,17,FALSE) -> 89 | AK34: =VLOOKUP(A34,ffbbudgettwofive,18,FALSE) -> 81
B36: =B37 -> 2015 | C36: =SUM(C37:C43) -> 174.6 | D36: =SUM(D37:D43) -> 937 | E36: =SUM(E37:E43) -> 145.78 | F36: =SUM(F37:F43) -> 843 | G36: =SUM(G37:G43) -> 1688.28 | H36: =G36-E36 -> 1542.5 | I36: =E36/C36 -> 0.834937 | J36: =G36/C36 -> 9.6694158 | Z36: Jan | AA36: Feb | AB36: Mar | AC36: Apr | AD36: May | AE36: Jun | AF36: Jul | AG36: Aug | AH36: Sep | AI36: Oct | AJ36: Nov | AK36: Dec
A37: 25 | B37: =VLOOKUP(A37,coupe,3,FALSE) -> 2015 | C37: =VLOOKUP(A37,WENDERLINUS,2,FALSE) -> 38.2 | D37: =VLOOKUP(A37,budget2026,19,FALSE) -> 151 | E37: =VLOOKUP(A37,year2022to23,374,FALSE) -> 22.67 | F37: =VLOOKUP(A37,coupe,4,FALSE) -> 134 | G37: =VLOOKUP(A37,year2022to23,313,FALSE) -> 330.31 | H37: =G37-E37 -> 307.64 | I37: =E37/C37 -> 0.5934555 | J37: =G37/C37 -> 8.6468586 | Z37: =VLOOKUP(A37,ffbbudgettwofive,7,FALSE) -> 6.7 | AA37: =VLOOKUP(A37,ffbbudgettwofive,8,FALSE) -> 5.36 | AB37: =VLOOKUP(A37,ffbbudgettwofive,9,FALSE) -> 9.38 | AC37: =VLOOKUP(A37,ffbbudgettwofive,10,FALSE) -> 9.38 | AD37: =VLOOKUP(A37,ffbbudgettwofive,11,FALSE) -> 9.38 | AE37: =VLOOKUP(A37,ffbbudgettwofive,12,FALSE) -> 9.38 | AF37: =VLOOKUP(A37,ffbbudgettwofive,13,FALSE) -> 11 | AG37: =VLOOKUP(A37,ffbbudgettwofive,14,FALSE) -> 13 | AH37: =VLOOKUP(A37,ffbbudgettwofive,15,FALSE) -> 13 | AI37: =VLOOKUP(A37,ffbbudgettwofive,16,FALSE) -> 19 | AJ37: =VLOOKUP(A37,ffbbudgettwofive,17,FALSE) -> 15 | AK37: =VLOOKUP(A37,ffbbudgettwofive,18,FALSE) -> 13
A38: 26A | B38: =VLOOKUP(A38,coupe,3,FALSE) -> 2015 | C38: =VLOOKUP(A38,WENDERLINUS,2,FALSE) -> 22.7 | D38: =VLOOKUP(A38,budget2026,19,FALSE) -> 133 | E38: =VLOOKUP(A38,year2022to23,374,FALSE) -> 25.08 | F38: =VLOOKUP(A38,coupe,4,FALSE) -> 108 | G38: =VLOOKUP(A38,year2022to23,313,FALSE) -> 281.24 | H38: =G38-E38 -> 256.16 | I38: =E38/C38 -> 1.1048458 | J38: =G38/C38 -> 12.389427 | Z38: =VLOOKUP(A38,ffbbudgettwofive,7,FALSE) -> 5.4 | AA38: =VLOOKUP(A38,ffbbudgettwofive,8,FALSE) -> 4.32 | AB38: =VLOOKUP(A38,ffbbudgettwofive,9,FALSE) -> 7.56 | AC38: =VLOOKUP(A38,ffbbudgettwofive,10,FALSE) -> 7.56 | AD38: =VLOOKUP(A38,ffbbudgettwofive,11,FALSE) -> 7.56 | AE38: =VLOOKUP(A38,ffbbudgettwofive,12,FALSE) -> 7.56 | AF38: =VLOOKUP(A38,ffbbudgettwofive,13,FALSE) -> 9 | AG38: =VLOOKUP(A38,ffbbudgettwofive,14,FALSE) -> 11 | AH38: =VLOOKUP(A38,ffbbudgettwofive,15,FALSE) -> 11 | AI38: =VLOOKUP(A38,ffbbudgettwofive,16,FALSE) -> 15 | AJ38: =VLOOKUP(A38,ffbbudgettwofive,17,FALSE) -> 12 | AK38: =VLOOKUP(A38,ffbbudgettwofive,18,FALSE) -> 11
A39: 27 | B39: =VLOOKUP(A39,coupe,3,FALSE) -> 2015 | C39: =VLOOKUP(A39,WENDERLINUS,2,FALSE) -> 14.3 | D39: =VLOOKUP(A39,budget2026,19,FALSE) -> 85 | E39: =VLOOKUP(A39,year2022to23,374,FALSE) -> 17.05 | F39: =VLOOKUP(A39,coupe,4,FALSE) -> 86 | G39: =VLOOKUP(A39,year2022to23,313,FALSE) -> 191.64 | H39: =G39-E39 -> 174.59 | I39: =E39/C39 -> 1.1923077 | J39: =G39/C39 -> 13.401399 | Z39: =VLOOKUP(A39,ffbbudgettwofive,7,FALSE) -> 4.3 | AA39: =VLOOKUP(A39,ffbbudgettwofive,8,FALSE) -> 3.44 | AB39: =VLOOKUP(A39,ffbbudgettwofive,9,FALSE) -> 6.02 | AC39: =VLOOKUP(A39,ffbbudgettwofive,10,FALSE) -> 6.02 | AD39: =VLOOKUP(A39,ffbbudgettwofive,11,FALSE) -> 6.02 | AE39: =VLOOKUP(A39,ffbbudgettwofive,12,FALSE) -> 6.02 | AF39: =VLOOKUP(A39,ffbbudgettwofive,13,FALSE) -> 7 | AG39: =VLOOKUP(A39,ffbbudgettwofive,14,FALSE) -> 9 | AH39: =VLOOKUP(A39,ffbbudgettwofive,15,FALSE) -> 9 | AI39: =VLOOKUP(A39,ffbbudgettwofive,16,FALSE) -> 12 | AJ39: =VLOOKUP(A39,ffbbudgettwofive,17,FALSE) -> 9 | AK39: =VLOOKUP(A39,ffbbudgettwofive,18,FALSE) -> 9
A40: 28 | B40: =VLOOKUP(A40,coupe,3,FALSE) -> 2015 | C40: =VLOOKUP(A40,WENDERLINUS,2,FALSE) -> 21.9 | D40: =VLOOKUP(A40,budget2026,19,FALSE) -> 262 | E40: =VLOOKUP(A40,year2022to23,374,FALSE) -> 29.27 | F40: =VLOOKUP(A40,coupe,4,FALSE) -> 256 | G40: =VLOOKUP(A40,year2022to23,313,FALSE) -> 331.57 | H40: =G40-E40 -> 302.3 | I40: =E40/C40 -> 1.3365297 | J40: =G40/C40 -> 15.140183 | Z40: =VLOOKUP(A40,ffbbudgettwofive,7,FALSE) -> 12.8 | AA40: =VLOOKUP(A40,ffbbudgettwofive,8,FALSE) -> 10.24 | AB40: =VLOOKUP(A40,ffbbudgettwofive,9,FALSE) -> 17.92 | AC40: =VLOOKUP(A40,ffbbudgettwofive,10,FALSE) -> 17.92 | AD40: =VLOOKUP(A40,ffbbudgettwofive,11,FALSE) -> 17.92 | AE40: =VLOOKUP(A40,ffbbudgettwofive,12,FALSE) -> 17.92 | AF40: =VLOOKUP(A40,ffbbudgettwofive,13,FALSE) -> 21 | AG40: =VLOOKUP(A40,ffbbudgettwofive,14,FALSE) -> 26 | AH40: =VLOOKUP(A40,ffbbudgettwofive,15,FALSE) -> 26 | AI40: =VLOOKUP(A40,ffbbudgettwofive,16,FALSE) -> 36 | AJ40: =VLOOKUP(A40,ffbbudgettwofive,17,FALSE) -> 28 | AK40: =VLOOKUP(A40,ffbbudgettwofive,18,FALSE) -> 26
A41: 29 | B41: =VLOOKUP(A41,coupe,3,FALSE) -> 2015 | C41: =VLOOKUP(A41,ERDI,2,FALSE) -> 19.2 | D41: =VLOOKUP(A41,budget2026,19,FALSE) -> 76 | E41: =VLOOKUP(A41,year2022to23,374,FALSE) -> 9.75 | F41: =VLOOKUP(A41,coupe,4,FALSE) -> 69 | G41: =VLOOKUP(A41,year2022to23,313,FALSE) -> 97.54 | H41: =G41-E41 -> 87.79 | I41: =E41/C41 -> 0.5078125 | J41: =G41/C41 -> 5.0802083 | Z41: =VLOOKUP(A41,ffbbudgettwofive,7,FALSE) -> 3.45 | AA41: =VLOOKUP(A41,ffbbudgettwofive,8,FALSE) -> 2.76 | AB41: =VLOOKUP(A41,ffbbudgettwofive,9,FALSE) -> 4.83 | AC41: =VLOOKUP(A41,ffbbudgettwofive,10,FALSE) -> 4.83 | AD41: =VLOOKUP(A41,ffbbudgettwofive,11,FALSE) -> 4.83 | AE41: =VLOOKUP(A41,ffbbudgettwofive,12,FALSE) -> 4.83 | AF41: =VLOOKUP(A41,ffbbudgettwofive,13,FALSE) -> 6 | AG41: =VLOOKUP(A41,ffbbudgettwofive,14,FALSE) -> 7 | AH41: =VLOOKUP(A41,ffbbudgettwofive,15,FALSE) -> 7 | AI41: =VLOOKUP(A41,ffbbudgettwofive,16,FALSE) -> 10 | AJ41: =VLOOKUP(A41,ffbbudgettwofive,17,FALSE) -> 8 | AK41: =VLOOKUP(A41,ffbbudgettwofive,18,FALSE) -> 7
A42: 30 | B42: =VLOOKUP(A42,coupe,3,FALSE) -> 2015 | C42: =VLOOKUP(A42,WENDERLINUS,2,FALSE) -> 24.3 | D42: =VLOOKUP(A42,budget2026,19,FALSE) -> 95 | E42: =VLOOKUP(A42,year2022to23,374,FALSE) -> 20.95 | F42: =VLOOKUP(A42,coupe,4,FALSE) -> 74 | G42: =VLOOKUP(A42,year2022to23,313,FALSE) -> 222.79 | H42: =G42-E42 -> 201.84 | I42: =E42/C42 -> 0.86213992 | J42: =G42/C42 -> 9.1683128 | Z42: =VLOOKUP(A42,ffbbudgettwofive,7,FALSE) -> 3.7 | AA42: =VLOOKUP(A42,ffbbudgettwofive,8,FALSE) -> 2.96 | AB42: =VLOOKUP(A42,ffbbudgettwofive,9,FALSE) -> 5.18 | AC42: =VLOOKUP(A42,ffbbudgettwofive,10,FALSE) -> 5.18 | AD42: =VLOOKUP(A42,ffbbudgettwofive,11,FALSE) -> 5.18 | AE42: =VLOOKUP(A42,ffbbudgettwofive,12,FALSE) -> 5.18 | AF42: =VLOOKUP(A42,ffbbudgettwofive,13,FALSE) -> 6 | AG42: =VLOOKUP(A42,ffbbudgettwofive,14,FALSE) -> 7 | AH42: =VLOOKUP(A42,ffbbudgettwofive,15,FALSE) -> 7 | AI42: =VLOOKUP(A42,ffbbudgettwofive,16,FALSE) -> 10 | AJ42: =VLOOKUP(A42,ffbbudgettwofive,17,FALSE) -> 8 | AK42: =VLOOKUP(A42,ffbbudgettwofive,18,FALSE) -> 7
A43: 31 | B43: =VLOOKUP(A43,coupe,3,FALSE) -> 2015 | C43: =VLOOKUP(A43,WENDERLINUS,2,FALSE) -> 34 | D43: =VLOOKUP(A43,budget2026,19,FALSE) -> 135 | E43: =VLOOKUP(A43,year2022to23,374,FALSE) -> 21.01 | F43: =VLOOKUP(A43,coupe,4,FALSE) -> 116 | G43: =VLOOKUP(A43,year2022to23,313,FALSE) -> 233.19 | H43: =G43-E43 -> 212.18 | I43: =E43/C43 -> 0.61794118 | J43: =G43/C43 -> 6.8585294 | Z43: =VLOOKUP(A43,ffbbudgettwofive,7,FALSE) -> 5.8 | AA43: =VLOOKUP(A43,ffbbudgettwofive,8,FALSE) -> 4.64 | AB43: =VLOOKUP(A43,ffbbudgettwofive,9,FALSE) -> 8.12 | AC43: =VLOOKUP(A43,ffbbudgettwofive,10,FALSE) -> 8.12 | AD43: =VLOOKUP(A43,ffbbudgettwofive,11,FALSE) -> 8.12 | AE43: =VLOOKUP(A43,ffbbudgettwofive,12,FALSE) -> 8.12 | AF43: =VLOOKUP(A43,ffbbudgettwofive,13,FALSE) -> 9 | AG43: =VLOOKUP(A43,ffbbudgettwofive,14,FALSE) -> 12 | AH43: =VLOOKUP(A43,ffbbudgettwofive,15,FALSE) -> 12 | AI43: =VLOOKUP(A43,ffbbudgettwofive,16,FALSE) -> 16 | AJ43: =VLOOKUP(A43,ffbbudgettwofive,17,FALSE) -> 13 | AK43: =VLOOKUP(A43,ffbbudgettwofive,18,FALSE) -> 12
B45: =B46 -> 2016 | C45: =SUM(C46:C47) -> 32.9 | D45: =SUM(D46:D47) -> 454 | E45: =SUM(E46:E47) -> 28.5 | F45: =SUM(F46:F47) -> 458 | G45: =SUM(G46:G47) -> 517.73 | H45: =G45-E45 -> 489.23 | I45: =E45/C45 -> 0.8662614 | J45: =G45/C45 -> 15.736474 | Z45: Jan | AA45: Feb | AB45: Mar | AC45: Apr | AD45: May | AE45: Jun | AF45: Jul | AG45: Aug | AH45: Sep | AI45: Oct | AJ45: Nov | AK45: Dec
A46: 33 | B46: =VLOOKUP(A46,coupe,3,FALSE) -> 2016 | C46: =VLOOKUP(A46,WENDERLINUS,2,FALSE) -> 28.4 | D46: =VLOOKUP(A46,budget2026,19,FALSE) -> 427 | E46: =VLOOKUP(A46,year2022to23,374,FALSE) -> 25.57 | F46: =VLOOKUP(A46,coupe,4,FALSE) -> 431 | G46: =VLOOKUP(A46,year2022to23,313,FALSE) -> 478.1 | H46: =G46-E46 -> 452.53 | I46: =E46/C46 -> 0.90035211 | J46: =G46/C46 -> 16.834507 | Z46: =VLOOKUP(A46,ffbbudgettwofive,7,FALSE) -> 21.55 | AA46: =VLOOKUP(A46,ffbbudgettwofive,8,FALSE) -> 17.24 | AB46: =VLOOKUP(A46,ffbbudgettwofive,9,FALSE) -> 30.17 | AC46: =VLOOKUP(A46,ffbbudgettwofive,10,FALSE) -> 30.17 | AD46: =VLOOKUP(A46,ffbbudgettwofive,11,FALSE) -> 30.17 | AE46: =VLOOKUP(A46,ffbbudgettwofive,12,FALSE) -> 30.17 | AF46: =VLOOKUP(A46,ffbbudgettwofive,13,FALSE) -> 34 | AG46: =VLOOKUP(A46,ffbbudgettwofive,14,FALSE) -> 43 | AH46: =VLOOKUP(A46,ffbbudgettwofive,15,FALSE) -> 43 | AI46: =VLOOKUP(A46,ffbbudgettwofive,16,FALSE) -> 60 | AJ46: =VLOOKUP(A46,ffbbudgettwofive,17,FALSE) -> 47 | AK46: =VLOOKUP(A46,ffbbudgettwofive,18,FALSE) -> 43
...

Sheet OVERALL BY GANG COMPARISON V3
A1: HARVESTER PERFORMANCE COMPARISON FOR CURRENT MONTH VS. PREVIOUS MONTH & VS PAST YEAR'S MONTH
A2: 46023
D3: 2026
D4: FFB PRODUCTION OF THE MONTH | H4: Budget 2026 (MT) | I4: MT / HA OF THE MONTH | K4: YTD | M4: YTD MT / HA
A5: Gang | C5: Total HA | D5: 1st Round (MT) | E5: 2nd Round (MT) | F5: 3rd Round (MT) | G5: Actual Total (MT) | I5: Actual | J5: Budget 2026 | K5: Actual | L5: Budget 2026 | M5: Actual | N5: Budget 2026
A6: YUVENTUS UN GANG | C6: ='YUVENTUS UN GANG'!B10 -> 163.73 | D6: ='YUVENTUS UN GANG'!D10 -> 146.76 | E6: ='YUVENTUS UN GANG'!E10 -> 63.45 | F6: ='YUVENTUS UN GANG'!F10 -> 2.61 | G6: =SUM(D6:F6) -> 212.82 | H6: ='YUVENTUS UN GANG'!C10 -> 190.06 | I6: =G6/C6 -> 1.2998229 | J6: =H6/C6 -> 1.1608135 | K6: =SUM(K7:K9) -> 212.82 | L6: =SUM(L7:L9) -> 190.06 | M6: =K6/C6 -> 1.2998229 | N6: =SUM(N7:N9)/C6 -> 1.1608135
B7: 1 | C7: =VLOOKUP(B7,YUVENTUS,2,FALSE) -> 53.09 | D7: =VLOOKUP(B7,YUVENTUS,4,FALSE) -> 44.13 | E7: =VLOOKUP(B7,YUVENTUS,5,FALSE) -> 20.15 | F7: =VLOOKUP(B7,YUVENTUS,6,FALSE) -> 0 | G7: =SUM(D7:F7) -> 64.28 | H7: =VLOOKUP(B7,YUVENTUS,3,FALSE) -> 61.54 | I7: =G7/C7 -> 1.2107742 | J7: =H7/C7 -> 1.1591637 | K7: =VLOOKUP(B7,year2022to23,374,FALSE) -> 64.28 | L7: =VLOOKUP(B7,YUVENTUS,3,FALSE) -> 61.54 | M7: =K7/C7 -> 1.2107742 | N7: =VLOOKUP(B7,budget2026,7,FALSE) -> 61.54
B8: 3 | C8: =VLOOKUP(B8,YUVENTUS,2,FALSE) -> 69.04 | D8: =VLOOKUP(B8,YUVENTUS,4,FALSE) -> 60.98 | E8: =VLOOKUP(B8,YUVENTUS,5,FALSE) -> 25.28 | F8: =VLOOKUP(B8,YUVENTUS,6,FALSE) -> 0 | G8: =SUM(D8:F8) -> 86.26 | H8: =VLOOKUP(B8,YUVENTUS,3,FALSE) -> 78.72 | I8: =G8/C8 -> 1.2494206 | J8: =H8/C8 -> 1.1402086 | K8: =VLOOKUP(B8,year2022to23,374,FALSE) -> 86.26 | L8: =VLOOKUP(B8,YUVENTUS,3,FALSE) -> 78.72 | M8: =K8/C8 -> 1.2494206 | N8: =VLOOKUP(B8,budget2026,7,FALSE) -> 78.72
B9: 14 | C9: =VLOOKUP(B9,YUVENTUS,2,FALSE) -> 41.6 | D9: =VLOOKUP(B9,YUVENTUS,4,FALSE) -> 41.65 | E9: =VLOOKUP(B9,YUVENTUS,5,FALSE) -> 18.02 | F9: =VLOOKUP(B9,YUVENTUS,6,FALSE) -> 2.61 | G9: =SUM(D9:F9) -> 62.28 | H9: =VLOOKUP(B9,YUVENTUS,3,FALSE) -> 49.8 | I9: =G9/C9 -> 1.4971154 | J9: =H9/C9 -> 1.1971154 | K9: =VLOOKUP(B9,year2022to23,374,FALSE) -> 62.28 | L9: =VLOOKUP(B9,YUVENTUS,3,FALSE) -> 49.8 | M9: =K9/C9 -> 1.4971154 | N9: =VLOOKUP(B9,budget2026,7,FALSE) -> 49.8
A11: DARSO GANG | C11: ='DARSO GANG'!B14 -> 383.61 | D11: ='DARSO GANG'!D14 -> 219.51 | E11: ='DARSO GANG'!E14 -> 135.8 | F11: ='DARSO GANG'!F14 -> 119.08 | G11: =SUM(D11:F11) -> 474.39 | H11: ='DARSO GANG'!C14 -> 466.2 | I11: =G11/C11 -> 1.2366466 | J11: =H11/C11 -> 1.2152968 | K11: =SUM(K12:K18) -> 474.39 | L11: =SUM(L12:L18) -> 466.2 | M11: =K11/C11 -> 1.2366466 | N11: =SUM(N12:N18)/C11 -> 1.2152968
B12: 15 | C12: =VLOOKUP(B12,DARSO,2,FALSE) -> 49.17 | D12: =VLOOKUP(B12,DARSO,4,FALSE) -> 33.38 | E12: =VLOOKUP(B12,DARSO,5,FALSE) -> 10.51 | F12: =VLOOKUP(B12,DARSO,6,FALSE) -> 20.07 | G12: =SUM(D12:F12) -> 63.96 | H12: =VLOOKUP(B12,DARSO,3,FALSE) -> 56.34 | I12: =G12/C12 -> 1.3007932 | J12: =H12/C12 -> 1.1458206 | K12: =VLOOKUP(B12,year2022to23,374,FALSE) -> 63.96 | L12: =VLOOKUP(B12,DARSO,3,FALSE) -> 56.34 | M12: =K12/C12 -> 1.3007932 | N12: =VLOOKUP(B12,budget2026,7,FALSE) -> 56.34
B13: 16 | C13: =VLOOKUP(B13,DARSO,2,FALSE) -> 52.61 | D13: =VLOOKUP(B13,DARSO,4,FALSE) -> 36.95 | E13: =VLOOKUP(B13,DARSO,5,FALSE) -> 21.07 | F13: =VLOOKUP(B13,DARSO,6,FALSE) -> 22.21 | G13: =SUM(D13:F13) -> 80.23 | H13: =VLOOKUP(B13,DARSO,3,FALSE) -> 60.48 | I13: =G13/C13 -> 1.5249952 | J13: =H13/C13 -> 1.1495913 | K13: =VLOOKUP(B13,year2022to23,374,FALSE) -> 80.23 | L13: =VLOOKUP(B13,DARSO,3,FALSE) -> 60.48 | M13: =K13/C13 -> 1.5249952 | N13: =VLOOKUP(B13,budget2026,7,FALSE) -> 60.48
B14: 17 | C14: =VLOOKUP(B14,DARSO,2,FALSE) -> 45.58 | D14: =VLOOKUP(B14,DARSO,4,FALSE) -> 25.86 | E14: =VLOOKUP(B14,DARSO,5,FALSE) -> 13.43 | F14: =VLOOKUP(B14,DARSO,6,FALSE) -> 18.86 | G14: =SUM(D14:F14) -> 58.15 | H14: =VLOOKUP(B14,DARSO,3,FALSE) -> 57.42 | I14: =G14/C14 -> 1.2757789 | J14: =H14/C14 -> 1.2597631 | K14: =VLOOKUP(B14,year2022to23,374,FALSE) -> 58.15 | L14: =VLOOKUP(B14,DARSO,3,FALSE) -> 57.42 | M14: =K14/C14 -> 1.2757789 | N14: =VLOOKUP(B14,budget2026,7,FALSE) -> 57.42
B15: 19 | C15: =VLOOKUP(B15,DARSO,2,FALSE) -> 50.6 | D15: =VLOOKUP(B15,DARSO,4,FALSE) -> 19.59 | E15: =VLOOKUP(B15,DARSO,5,FALSE) -> 14.64 | F15: =VLOOKUP(B15,DARSO,6,FALSE) -> 10.05 | G15: =SUM(D15:F15) -> 44.28 | H15: =VLOOKUP(B15,DARSO,3,FALSE) -> 60.48 | I15: =G15/C15 -> 0.87509881 | J15: =H15/C15 -> 1.1952569 | K15: =VLOOKUP(B15,year2022to23,374,FALSE) -> 44.28 | L15: =VLOOKUP(B15,DARSO,3,FALSE) -> 60.48 | M15: =K15/C15 -> 0.87509881 | N15: =VLOOKUP(B15,budget2026,7,FALSE) -> 60.48
B16: 20 | C16: =VLOOKUP(B16,DARSO,2,FALSE) -> 61.98 | D16: =VLOOKUP(B16,DARSO,4,FALSE) -> 29.87 | E16: =VLOOKUP(B16,DARSO,5,FALSE) -> 19.36 | F16: =VLOOKUP(B16,DARSO,6,FALSE) -> 0 | G16: =SUM(D16:F16) -> 49.23 | H16: =VLOOKUP(B16,DARSO,3,FALSE) -> 74.16 | I16: =G16/C16 -> 0.79428848 | J16: =H16/C16 -> 1.196515 | K16: =VLOOKUP(B16,year2022to23,374,FALSE) -> 49.23 | L16: =VLOOKUP(B16,DARSO,3,FALSE) -> 74.16 | M16: =K16/C16 -> 0.79428848 | N16: =VLOOKUP(B16,budget2026,7,FALSE) -> 74.16
B17: 21 | C17: =VLOOKUP(B17,DARSO,2,FALSE) -> 71.59 | D17: =VLOOKUP(B17,DARSO,4,FALSE) -> 32.61 | E17: =VLOOKUP(B17,DARSO,5,FALSE) -> 37.53 | F17: =VLOOKUP(B17,DARSO,6,FALSE) -> 23.66 | G17: =SUM(D17:F17) -> 93.8 | H17: =VLOOKUP(B17,DARSO,3,FALSE) -> 94.56 | I17: =G17/C17 -> 1.3102389 | J17: =H17/C17 -> 1.3208549 | K17: =VLOOKUP(B17,year2022to23,374,FALSE) -> 93.8 | L17: =VLOOKUP(B17,DARSO,3,FALSE) -> 94.56 | M17: =K17/C17 -> 1.3102389 | N17: =VLOOKUP(B17,budget2026,7,FALSE) -> 94.56
B18: 22 | C18: =VLOOKUP(B18,DARSO,2,FALSE) -> 52.08 | D18: =VLOOKUP(B18,DARSO,4,FALSE) -> 41.25 | E18: =VLOOKUP(B18,DARSO,5,FALSE) -> 19.26 | F18: =VLOOKUP(B18,DARSO,6,FALSE) -> 24.23 | G18: =SUM(D18:F18) -> 84.74 | H18: =VLOOKUP(B18,DARSO,3,FALSE) -> 62.76 | I18: =G18/C18 -> 1.6271121 | J18: =H18/C18 -> 1.2050691 | K18: =VLOOKUP(B18,year2022to23,374,FALSE) -> 84.74 | L18: =VLOOKUP(B18,DARSO,3,FALSE) -> 62.76 | M18: =K18/C18 -> 1.6271121 | N18: =VLOOKUP(B18,budget2026,7,FALSE) -> 62.76
A20: YUDI GANG -previously ERDI GANG | C20: ='YUDI GANG'!B10 -> 123.97 | D20: ='YUDI GANG'!D10 -> 44.26 | E20: ='YUDI GANG'!E10 -> 106.03 | F20: ='YUDI GANG'!F10 -> 0 | G20: =SUM(D20:F20) -> 150.29 | H20: ='YUDI GANG'!C10 -> 119.86 | I20: =G20/C20 -> 1.2123094 | J20: =H20/C20 -> 0.96684682 | K20: =SUM(K21:K23) -> 150.29 | L20: =SUM(L21:L23) -> 119.86 | M20: =K20/C20 -> 1.2123094 | N20: =SUM(N21:N23)/C20 -> 0.96684682
B21: 2 | C21: =VLOOKUP(B21,ERDI,2,FALSE) -> 60.27 | D21: =VLOOKUP(B21,ERDI,4,FALSE) -> 3.25 | E21: =VLOOKUP(B21,ERDI,5,FALSE) -> 86.72 | F21: =VLOOKUP(B21,ERDI,6,FALSE) -> 0 | G21: =SUM(D21:F21) -> 89.97 | H21: =VLOOKUP(B21,ERDI,3,FALSE) -> 68.06 | I21: =G21/C21 -> 1.4927825 | J21: =H21/C21 -> 1.1292517 | K21: =VLOOKUP(B21,year2022to23,374,FALSE) -> 89.97 | L21: =VLOOKUP(B21,ERDI,3,FALSE) -> 68.06 | M21: =K21/C21 -> 1.4927825 | N21: =VLOOKUP(B21,budget2026,7,FALSE) -> 68.06
B22: 11 | C22: =VLOOKUP(B22,ERDI,2,FALSE) -> 44.5 | D22: =VLOOKUP(B22,ERDI,4,FALSE) -> 34.84 | E22: =VLOOKUP(B22,ERDI,5,FALSE) -> 15.73 | F22: =VLOOKUP(B22,ERDI,6,FALSE) -> 0 | G22: =SUM(D22:F22) -> 50.57 | H22: =VLOOKUP(B22,ERDI,3,FALSE) -> 48.24 | I22: =G22/C22 -> 1.1364045 | J22: =H22/C22 -> 1.0840449 | K22: =VLOOKUP(B22,year2022to23,374,FALSE) -> 50.57 | L22: =VLOOKUP(B22,ERDI,3,FALSE) -> 48.24 | M22: =K22/C22 -> 1.1364045 | N22: =VLOOKUP(B22,budget2026,7,FALSE) -> 48.24
B23: 29 | C23: =VLOOKUP(B23,ERDI,2,FALSE) -> 19.2 | D23: =VLOOKUP(B23,ERDI,4,FALSE) -> 6.17 | E23: =VLOOKUP(B23,ERDI,5,FALSE) -> 3.58 | F23: =VLOOKUP(B23,ERDI,6,FALSE) -> 0 | G23: =SUM(D23:F23) -> 9.75 | H23: =VLOOKUP(B23,ERDI,3,FALSE) -> 3.56 | I23: =G23/C23 -> 0.5078125 | J23: =H23/C23 -> 0.18541667 | K23: =VLOOKUP(B23,year2022to23,374,FALSE) -> 9.75 | L23: =VLOOKUP(B23,ERDI,3,FALSE) -> 3.56 | M23: =K23/C23 -> 0.5078125 | N23: =VLOOKUP(B23,budget2026,7,FALSE) -> 3.56
A25: SOFIO MODENTUS MISSA GANG - previously SERAN | C25: ='SOFIO GANG'!B13 -> 262.38 | D25: ='SOFIO GANG'!D13 -> 197.08 | E25: ='SOFIO GANG'!E13 -> 68.68 | F25: ='SOFIO GANG'!F13 -> 2.51 | G25: =SUM(D25:F25) -> 268.27 | H25: ='SOFIO GANG'!C13 -> 291.64 | I25: =G25/C25 -> 1.0224484 | J25: =H25/C25 -> 1.1115176 | K25: =SUM(K26:K31) -> 268.27 | L25: =SUM(L26:L31) -> 291.64 | M25: =K25/C25 -> 1.0224484 | N25: =SUM(N26:N31)/C25 -> 1.1115176
B26: 4 | C26: =VLOOKUP(B26,SERAN,2,FALSE) -> 70.51 | D26: =VLOOKUP(B26,SERAN,4,FALSE) -> 56.01 | E26: =VLOOKUP(B26,SERAN,5,FALSE) -> 14.9 | F26: =VLOOKUP(B26,SERAN,6,FALSE) -> 0 | G26: =SUM(D26:F26) -> 70.91 | H26: =VLOOKUP(B26,SERAN,3,FALSE) -> 81.46 | I26: =G26/C26 -> 1.005673 | J26: =H26/C26 -> 1.1552971 | K26: =VLOOKUP(B26,year2022to23,374,FALSE) -> 70.91 | L26: =VLOOKUP(B26,SERAN,3,FALSE) -> 81.46 | M26: =K26/C26 -> 1.005673 | N26: =VLOOKUP(B26,budget2026,7,FALSE) -> 81.46
B27: 5 | C27: =VLOOKUP(B27,SERAN,2,FALSE) -> 50.4 | D27: =VLOOKUP(B27,SERAN,4,FALSE) -> 15.7 | E27: =VLOOKUP(B27,SERAN,5,FALSE) -> 20.68 | F27: =VLOOKUP(B27,SERAN,6,FALSE) -> 2.51 | G27: =SUM(D27:F27) -> 38.89 | H27: =VLOOKUP(B27,SERAN,3,FALSE) -> 57.48 | I27: =G27/C27 -> 0.77162698 | J27: =H27/C27 -> 1.1404762 | K27: =VLOOKUP(B27,year2022to23,374,FALSE) -> 38.89 | L27: =VLOOKUP(B27,SERAN,3,FALSE) -> 57.48 | M27: =K27/C27 -> 0.77162698 | N27: =VLOOKUP(B27,budget2026,7,FALSE) -> 57.48
B28: 6 | C28: =VLOOKUP(B28,SERAN,2,FALSE) -> 58.6 | D28: =VLOOKUP(B28,SERAN,4,FALSE) -> 40.3 | E28: =VLOOKUP(B28,SERAN,5,FALSE) -> 15.99 | F28: =VLOOKUP(B28,SERAN,6,FALSE) -> 0 | G28: =SUM(D28:F28) -> 56.29 | H28: =VLOOKUP(B28,SERAN,3,FALSE) -> 66.84 | I28: =G28/C28 -> 0.9605802 | J28: =H28/C28 -> 1.1406143 | K28: =VLOOKUP(B28,year2022to23,374,FALSE) -> 56.29 | L28: =VLOOKUP(B28,SERAN,3,FALSE) -> 66.84 | M28: =K28/C28 -> 0.9605802 | N28: =VLOOKUP(B28,budget2026,7,FALSE) -> 66.84
B29: 7 | C29: =VLOOKUP(B29,SERAN,2,FALSE) -> 23.6 | D29: =VLOOKUP(B29,SERAN,4,FALSE) -> 24.72 | E29: =VLOOKUP(B29,SERAN,5,FALSE) -> 0 | F29: =VLOOKUP(B29,SERAN,6,FALSE) -> 0 | G29: =SUM(D29:F29) -> 24.72 | H29: =VLOOKUP(B29,SERAN,3,FALSE) -> 22.86 | I29: =G29/C29 -> 1.0474576 | J29: =H29/C29 -> 0.96864407 | K29: =VLOOKUP(B29,year2022to23,374,FALSE) -> 24.72 | L29: =VLOOKUP(B29,SERAN,3,FALSE) -> 22.86 | M29: =K29/C29 -> 1.0474576 | N29: =VLOOKUP(B29,budget2026,7,FALSE) -> 22.86
B30: 23 | C30: =VLOOKUP(B30,SERAN,2,FALSE) -> 14.6 | D30: =VLOOKUP(B30,SERAN,4,FALSE) -> 17.37 | E30: =VLOOKUP(B30,SERAN,5,FALSE) -> 3.79 | F30: =VLOOKUP(B30,SERAN,6,FALSE) -> 0 | G30: =SUM(D30:F30) -> 21.16 | H30: =VLOOKUP(B30,SERAN,3,FALSE) -> 17.34 | I30: =G30/C30 -> 1.4493151 | J30: =H30/C30 -> 1.1876712 | K30: =VLOOKUP(B30,year2022to23,374,FALSE) -> 21.16 | L30: =VLOOKUP(B30,SERAN,3,FALSE) -> 17.34 | M30: =K30/C30 -> 1.4493151 | N30: =VLOOKUP(B30,budget2026,7,FALSE) -> 17.34
B31: 24 | C31: =VLOOKUP(B31,SERAN,2,FALSE) -> 44.67 | D31: =VLOOKUP(B31,SERAN,4,FALSE) -> 42.98 | E31: =VLOOKUP(B31,SERAN,5,FALSE) -> 13.32 | F31: =VLOOKUP(B31,SERAN,6,FALSE) -> 0 | G31: =SUM(D31:F31) -> 56.3 | H31: =VLOOKUP(B31,SERAN,3,FALSE) -> 45.66 | I31: =G31/C31 -> 1.2603537 | J31: =H31/C31 -> 1.0221625 | K31: =VLOOKUP(B31,year2022to23,374,FALSE) -> 56.3 | L31: =VLOOKUP(B31,SERAN,3,FALSE) -> 45.66 | M31: =K31/C31 -> 1.2603537 | N31: =VLOOKUP(B31,budget2026,7,FALSE) -> 45.66
A33: NU AZANI GANG | C33: ='NU AZANI GANG'!B13 -> 291.6 | D33: ='NU AZANI GANG'!D13 -> 254.45 | E33: ='NU AZANI GANG'!E13 -> 134.25 | F33: ='NU AZANI GANG'!F13 -> 9.36 | G33: =SUM(D33:F33) -> 398.06 | H33: ='NU AZANI GANG'!C13 -> 339.92 | I33: =G33/C33 -> 1.3650892 | J33: =H33/C33 -> 1.1657064 | K33: =SUM(K34:K39) -> 398.06 | L33: =SUM(L34:L39) -> 339.92 | M33: =K33/C33 -> 1.3650892 | N33: =SUM(N34:N39)/C33 -> 1.1657064
B34: 8 | C34: =VLOOKUP(B34,NURAZANI,2,FALSE) -> 61.6 | D34: =VLOOKUP(B34,NURAZANI,4,FALSE) -> 43.65 | E34: =VLOOKUP(B34,NURAZANI,5,FALSE) -> 36.49 | F34: =VLOOKUP(B34,NURAZANI,6,FALSE) -> 9.36 | G34: =SUM(D34:F34) -> 89.5 | H34: =VLOOKUP(B34,NURAZANI,3,FALSE) -> 70.3 | I34: =G34/C34 -> 1.4529221 | J34: =H34/C34 -> 1.1412338 | K34: =VLOOKUP(B34,year2022to23,374,FALSE) -> 89.5 | L34: =VLOOKUP(B34,NURAZANI,3,FALSE) -> 70.3 | M34: =K34/C34 -> 1.4529221 | N34: =VLOOKUP(B34,budget2026,7,FALSE) -> 70.3
B35: 9 | C35: =VLOOKUP(B35,NURAZANI,2,FALSE) -> 38.3 | D35: =VLOOKUP(B35,NURAZANI,4,FALSE) -> 28.68 | E35: =VLOOKUP(B35,NURAZANI,5,FALSE) -> 17.31 | F35: =VLOOKUP(B35,NURAZANI,6,FALSE) -> 0 | G35: =SUM(D35:F35) -> 45.99 | H35: =VLOOKUP(B35,NURAZANI,3,FALSE) -> 39.48 | I35: =G35/C35 -> 1.2007833 | J35: =H35/C35 -> 1.0308094 | K35: =VLOOKUP(B35,year2022to23,374,FALSE) -> 45.99 | L35: =VLOOKUP(B35,NURAZANI,3,FALSE) -> 39.48 | M35: =K35/C35 -> 1.2007833 | N35: =VLOOKUP(B35,budget2026,7,FALSE) -> 39.48
B36: 12 | C36: =VLOOKUP(B36,NURAZANI,2,FALSE) -> 71 | D36: =VLOOKUP(B36,NURAZANI,4,FALSE) -> 62.38 | E36: =VLOOKUP(B36,NURAZANI,5,FALSE) -> 22.2 | F36: =VLOOKUP(B36,NURAZANI,6,FALSE) -> 0 | G36: =SUM(D36:F36) -> 84.58 | H36: =VLOOKUP(B36,NURAZANI,3,FALSE) -> 81.88 | I36: =G36/C36 -> 1.1912676 | J36: =H36/C36 -> 1.1532394 | K36: =VLOOKUP(B36,year2022to23,374,FALSE) -> 84.58 | L36: =VLOOKUP(B36,NURAZANI,3,FALSE) -> 81.88 | M36: =K36/C36 -> 1.1912676 | N36: =VLOOKUP(B36,budget2026,7,FALSE) -> 81.88
B37: 10 | C37: =VLOOKUP(B37,NURAZANI,2,FALSE) -> 19.1 | D37: =VLOOKUP(B37,NURAZANI,4,FALSE) -> 17.56 | E37: =VLOOKUP(B37,NURAZANI,5,FALSE) -> 10.92 | F37: =VLOOKUP(B37,NURAZANI,6,FALSE) -> 0 | G37: =SUM(D37:F37) -> 28.48 | H37: =VLOOKUP(B37,NURAZANI,3,FALSE) -> 20.58 | I37: =G37/C37 -> 1.4910995 | J37: =H37/C37 -> 1.0774869 | K37: =VLOOKUP(B37,year2022to23,374,FALSE) -> 28.48 | L37: =VLOOKUP(B37,NURAZANI,3,FALSE) -> 20.58 | M37: =K37/C37 -> 1.4910995 | N37: =VLOOKUP(B37,budget2026,7,FALSE) -> 20.58
B38: 13 | C38: =VLOOKUP(B38,NURAZANI,2,FALSE) -> 60.8 | D38: =VLOOKUP(B38,NURAZANI,4,FALSE) -> 59.52 | E38: =VLOOKUP(B38,NURAZANI,5,FALSE) -> 29.65 | F38: =VLOOKUP(B38,NURAZANI,6,FALSE) -> 0 | G38: =SUM(D38:F38) -> 89.17 | H38: =VLOOKUP(B38,NURAZANI,3,FALSE) -> 76.32 | I38: =G38/C38 -> 1.4666118 | J38: =H38/C38 -> 1.2552632 | K38: =VLOOKUP(B38,year2022to23,374,FALSE) -> 89.17 | L38: =VLOOKUP(B38,NURAZANI,3,FALSE) -> 76.32 | M38: =K38/C38 -> 1.4666118 | N38: =VLOOKUP(B38,budget2026,7,FALSE) -> 76.32
B39: 18 | C39: =VLOOKUP(B39,NURAZANI,2,FALSE) -> 40.8 | D39: =VLOOKUP(B39,NURAZANI,4,FALSE) -> 42.66 | E39: =VLOOKUP(B39,NURAZANI,5,FALSE) -> 17.68 | F39: =VLOOKUP(B39,NURAZANI,6,FALSE) -> 0 | G39: =SUM(D39:F39) -> 60.34 | H39: =VLOOKUP(B39,NURAZANI,3,FALSE) -> 51.36 | I39: =G39/C39 -> 1.4789216 | J39: =H39/C39 -> 1.2588235 | K39: =VLOOKUP(B39,year2022to23,374,FALSE) -> 60.34 | L39: =VLOOKUP(B39,NURAZANI,3,FALSE) -> 51.36 | M39: =K39/C39 -> 1.4789216 | N39: =VLOOKUP(B39,budget2026,7,FALSE) -> 51.36
A41: WENDERLINUS GANG | C41: ='WENDERLINUS GANG '!B15 -> 188.3 | D41: ='WENDERLINUS GANG '!D15 -> 100.02 | E41: ='WENDERLINUS GANG '!E15 -> 61.36 | F41: ='WENDERLINUS GANG '!F15 -> 3.15 | G41: =SUM(D41:F41) -> 164.53 | H41: ='WENDERLINUS GANG '!C15 -> 73.9 | I41: =G41/C41 -> 0.87376527 | J41: =H41/C41 -> 0.39245884 | K41: =SUM(K42:K49) -> 164.53 | L41: =SUM(L42:L49) -> 73.9 | M41: =K41/C41 -> 0.87376527 | N41: =SUM(N42:N49)/C41 -> 0.39245884
B42: 25 | C42: =VLOOKUP(B42,WENDERLINUS,2,FALSE) -> 38.2 | D42: =VLOOKUP(B42,WENDERLINUS,4,FALSE) -> 16.68 | E42: =VLOOKUP(B42,WENDERLINUS,5,FALSE) -> 5.99 | F42: =VLOOKUP(B42,WENDERLINUS,6,FALSE) -> 0 | G42: =SUM(D42:F42) -> 22.67 | H42: =VLOOKUP(B42,WENDERLINUS,3,FALSE) -> 8.06 | I42: =G42/C42 -> 0.5934555 | J42: =H42/C42 -> 0.21099476 | K42: =VLOOKUP(B42,year2022to23,374,FALSE) -> 22.67 | L42: =VLOOKUP(B42,WENDERLINUS,3,FALSE) -> 8.06 | M42: =K42/C42 -> 0.5934555 | N42: =VLOOKUP(B42,budget2026,7,FALSE) -> 8.06
B43: 26A | C43: =VLOOKUP(B43,WENDERLINUS,2,FALSE) -> 22.7 | D43: =VLOOKUP(B43,WENDERLINUS,4,FALSE) -> 14.24 | E43: =VLOOKUP(B43,WENDERLINUS,5,FALSE) -> 10.84 | F43: =VLOOKUP(B43,WENDERLINUS,6,FALSE) -> 0 | G43: =SUM(D43:F43) -> 25.08 | H43: =VLOOKUP(B43,WENDERLINUS,3,FALSE) -> 5.98 | I43: =G43/C43 -> 1.1048458 | J43: =H43/C43 -> 0.26343612 | K43: =VLOOKUP(B43,year2022to23,374,FALSE) -> 25.08 | L43: =VLOOKUP(B43,WENDERLINUS,3,FALSE) -> 5.98 | M43: =K43/C43 -> 1.1048458 | N43: =VLOOKUP(B43,budget2026,7,FALSE) -> 5.98
B44: 27 | C44: =VLOOKUP(B44,WENDERLINUS,2,FALSE) -> 14.3 | D44: =VLOOKUP(B44,WENDERLINUS,4,FALSE) -> 8.31 | E44: =VLOOKUP(B44,WENDERLINUS,5,FALSE) -> 8.74 | F44: =VLOOKUP(B44,WENDERLINUS,6,FALSE) -> 0 | G44: =SUM(D44:F44) -> 17.05 | H44: =VLOOKUP(B44,WENDERLINUS,3,FALSE) -> 5.1 | I44: =G44/C44 -> 1.1923077 | J44: =H44/C44 -> 0.35664336 | K44: =VLOOKUP(B44,year2022to23,374,FALSE) -> 17.05 | L44: =VLOOKUP(B44,WENDERLINUS,3,FALSE) -> 5.1 | M44: =K44/C44 -> 1.1923077 | N44: =VLOOKUP(B44,budget2026,7,FALSE) -> 5.1
B45: 28 | C45: =VLOOKUP(B45,WENDERLINUS,2,FALSE) -> 21.9 | D45: =VLOOKUP(B45,WENDERLINUS,4,FALSE) -> 16.89 | E45: =VLOOKUP(B45,WENDERLINUS,5,FALSE) -> 12.38 | F45: =VLOOKUP(B45,WENDERLINUS,6,FALSE) -> 0 | G45: =SUM(D45:F45) -> 29.27 | H45: =VLOOKUP(B45,WENDERLINUS,3,FALSE) -> 15.72 | I45: =G45/C45 -> 1.3365297 | J45: =H45/C45 -> 0.71780822 | K45: =VLOOKUP(B45,year2022to23,374,FALSE) -> 29.27 | L45: =VLOOKUP(B45,WENDERLINUS,3,FALSE) -> 15.72 | M45: =K45/C45 -> 1.3365297 | N45: =VLOOKUP(B45,budget2026,7,FALSE) -> 15.72
...

Sheet OVERALL
A1: ='HARVESTING ROUND'!A1 -> HARVESTER PERFORMANCE CHART FOR THE MONTH OF JAN 2026 (1ST - 31ST)
A2: OVERALL PERFORMANCE
A3: Block | B3: HA per Block | C3: Budget 2025 | D3: 1st Round | E3: 2nd Round | F3: 3rd Round | G3: Total
A4: All Blocks | B4: ='OVERALL BY GANG'!B10 -> 1413.59 | C4: ='OVERALL BY GANG'!C10 -> 1481.58 | D4: ='HARVESTING ROUND'!F36 -> 962.08 | E4: ='HARVESTING ROUND'!G36 -> 569.57 | F4: ='HARVESTING ROUND'!H36 -> 136.71 | G4: =SUM(D4:F4) -> 1668.36
E55: Sept-25 vs Aug-25 Diff. (%) | H55: Sept-25 vs Aug-25 Diff. (%)
E105: Sept-25 vs Sept-24 Diff. (%) | H105: Sept-25 vs Sept-24 Diff. (%)

Sheet OVERALL BY GANG
A1: ='HARVESTING ROUND'!A1 -> HARVESTER PERFORMANCE CHART FOR THE MONTH OF JAN 2026 (1ST - 31ST)
A2: OVERALL PERFORMANCE - BY HARVESTER GANG
A3: Gang | B3: Total HA | C3: Budget 2026 | D3: 1st Round | E3: 2nd Round | F3: 3rd Round | G3: Total | I3: Total Manpower | J3: Total on Long Leave | K3: Manday | L3: MT / Manday | M3: HA per person | N3: MT per person | O3: Ratio HA to MT per person
A4: YUVENTUS UN GANG | B4: ='YUVENTUS UN GANG'!B10 -> 163.73 | C4: ='YUVENTUS UN GANG'!C10 -> 190.06 | D4: ='YUVENTUS UN GANG'!D10 -> 146.76 | E4: ='YUVENTUS UN GANG'!E10 -> 63.45 | F4: ='YUVENTUS UN GANG'!F10 -> 2.61 | G4: =SUM(D4:F4) -> 212.82 | I4: ='YUVENTUS UN GANG'!$D$3 -> 10 | J4: ='YUVENTUS UN GANG'!$D$4 -> 0 | K4: ='YUVENTUS UN GANG'!I10 -> 229 | L4: =G4/K4 -> 0.92934498 | M4: ='YUVENTUS UN GANG'!$J$17 -> 16.373 | N4: ='YUVENTUS UN GANG'!$J$13 -> 21.282 | O4: ='YUVENTUS UN GANG'!J21 -> 1:1.3
A5: DARSO GANG | B5: ='DARSO GANG'!B14 -> 383.61 | C5: ='DARSO GANG'!C14 -> 466.2 | D5: ='DARSO GANG'!D14 -> 219.51 | E5: ='DARSO GANG'!E14 -> 135.8 | F5: ='DARSO GANG'!F14 -> 119.08 | G5: =SUM(D5:F5) -> 474.39 | I5: ='DARSO GANG'!D3 -> 17 | J5: ='DARSO GANG'!D4 -> 0 | K5: ='DARSO GANG'!I14 -> 371 | L5: =G5/K5 -> 1.2786792 | M5: ='DARSO GANG'!J21 -> 22.565294 | N5: ='DARSO GANG'!J17 -> 27.905294 | O5: ='DARSO GANG'!J25 -> 1:1.24
A6: ERDI GANG - to be taken by YUDI | B6: ='YUDI GANG'!B10 -> 123.97 | C6: ='YUDI GANG'!C10 -> 119.86 | D6: ='YUDI GANG'!D10 -> 44.26 | E6: ='YUDI GANG'!E10 -> 106.03 | F6: ='YUDI GANG'!F10 -> 0 | G6: =SUM(D6:F6) -> 150.29 | I6: ='YUDI GANG'!D3 -> 7 | J6: ='YUDI GANG'!D4 -> 0 | K6: ='YUDI GANG'!I10 -> 183 | L6: =G6/K6 -> 0.82125683 | M6: ='YUDI GANG'!J17 -> 17.71 | N6: ='YUDI GANG'!J13 -> 21.47 | O6: ='YUDI GANG'!J21 -> 1:1.21
A7: SOFIO MODENTUS MISSA GANG - previously SERAN | B7: ='SOFIO GANG'!B13 -> 262.38 | C7: ='SOFIO GANG'!C13 -> 291.64 | D7: ='SOFIO GANG'!D13 -> 197.08 | E7: ='SOFIO GANG'!E13 -> 68.68 | F7: ='SOFIO GANG'!F13 -> 2.51 | G7: =SUM(D7:F7) -> 268.27 | I7: ='SOFIO GANG'!D3 -> 12 | J7: ='SOFIO GANG'!D4 -> 0 | K7: ='SOFIO GANG'!I13 -> 267 | L7: =G7/K7 -> 1.0047566 | M7: ='SOFIO GANG'!J20 -> 21.865 | N7: ='SOFIO GANG'!J16 -> 22.355833 | O7: ='SOFIO GANG'!J24 -> 1:1.02
A8: NU AZANI GANG | B8: ='NU AZANI GANG'!B13 -> 291.6 | C8: ='NU AZANI GANG'!C13 -> 339.92 | D8: ='NU AZANI GANG'!D13 -> 254.45 | E8: ='NU AZANI GANG'!E13 -> 134.25 | F8: ='NU AZANI GANG'!F13 -> 9.36 | G8: =SUM(D8:F8) -> 398.06 | I8: ='NU AZANI GANG'!D3 -> 10 | J8: ='NU AZANI GANG'!D4 -> 0 | K8: ='NU AZANI GANG'!I13 -> 249 | L8: =G8/K8 -> 1.5986345 | M8: ='NU AZANI GANG'!J20 -> 29.16 | N8: ='NU AZANI GANG'!J16 -> 39.806 | O8: ='NU AZANI GANG'!J24 -> 1:1.37
A9: WENDERLINUS GANG | B9: ='WENDERLINUS GANG '!B15 -> 188.3 | C9: ='WENDERLINUS GANG '!C15 -> 73.9 | D9: ='WENDERLINUS GANG '!D15 -> 100.02 | E9: ='WENDERLINUS GANG '!E15 -> 61.36 | F9: ='WENDERLINUS GANG '!F15 -> 3.15 | G9: =SUM(D9:F9) -> 164.53 | I9: ='WENDERLINUS GANG '!D3 -> 7 | J9: ='WENDERLINUS GANG '!D4 -> 0 | K9: ='WENDERLINUS GANG '!I15 -> 192 | L9: =G9/K9 -> 0.85692708 | M9: ='WENDERLINUS GANG '!J22 -> 26.9 | N9: ='WENDERLINUS GANG '!J18 -> 23.504286 | O9: ='WENDERLINUS GANG '!J26 -> 1:0.87
A10: All Blocks | B10: =SUM(B4:B9) -> 1413.59 | C10: =SUM(C4:C9) -> 1481.58 | D10: =SUM(D4:D9) -> 962.08 | E10: =SUM(E4:E9) -> 569.57 | F10: =SUM(F4:F9) -> 136.71 | G10: =SUM(G4:G9) -> 1668.36 | I10: =SUM(I4:I9) -> 63 | J10: =SUM(J4:J9) -> 0 | K10: =SUM(K4:K9) -> 1491 | L10: =G10/K10 -> 1.1189537 | M10: =B10/(I10-J10) -> 22.437937 | N10: =G10/(I10-J10) -> 26.481905 | O10: =B10/B10&":"&ROUND(G10/B10,2) -> 1:1.18
E55: Sept-25 vs Aug-25 Diff. (%) | H55: Sept-25 vs Aug-25 Diff. (%)
E105: Sept-25 vs Sept-24 Diff. (%) | H105: Sept-25 vs Sept-24 Diff. (%)

Sheet YUVENTUS UN GANG
A1: ='HARVESTING ROUND'!A1 -> HARVESTER PERFORMANCE CHART FOR THE MONTH OF JAN 2026 (1ST - 31ST)
A2: HARVESTER TEAM: YUVENTUS UN GANG
A3: TOTAL MANPOWER: | D3: 10
A4: TOTAL ON LONG LEAVE: | D4: 0
A6: Block | B6: HA per Block | C6: Budget 2026 | D6: 1st Round | E6: 2nd Round | F6: 3rd Round | G6: Total | I6: Manday | J6: MT / Manday
A7: 1 | B7: =VLOOKUP(A7,budget2026,6,FALSE) -> 53.09 | C7: =VLOOKUP(A7,budget2026,7,FALSE) -> 61.54 | D7: =VLOOKUP(A7,harvestinground,5,FALSE) -> 44.13 | E7: =VLOOKUP(A7,harvestinground,6,FALSE) -> 20.15 | F7: =VLOOKUP(A7,harvestinground,7,FALSE) -> 0 | G7: =SUM(D7:F7) -> 64.28 | I7: =VLOOKUP(A7,manday,34,FALSE) -> 80 | J7: =G7/I7 -> 0.8035
A8: 3 | B8: =VLOOKUP(A8,budget2026,6,FALSE) -> 69.04 | C8: =VLOOKUP(A8,budget2026,7,FALSE) -> 78.72 | D8: =VLOOKUP(A8,harvestinground,5,FALSE) -> 60.98 | E8: =VLOOKUP(A8,harvestinground,6,FALSE) -> 25.28 | F8: =VLOOKUP(A8,harvestinground,7,FALSE) -> 0 | G8: =SUM(D8:F8) -> 86.26 | I8: =VLOOKUP(A8,manday,34,FALSE) -> 72 | J8: =G8/I8 -> 1.1980556
A9: 14 | B9: =VLOOKUP(A9,budget2026,6,FALSE) -> 41.6 | C9: =VLOOKUP(A9,budget2026,7,FALSE) -> 49.8 | D9: =VLOOKUP(A9,harvestinground,5,FALSE) -> 41.65 | E9: =VLOOKUP(A9,harvestinground,6,FALSE) -> 18.02 | F9: =VLOOKUP(A9,harvestinground,7,FALSE) -> 2.61 | G9: =SUM(D9:F9) -> 62.28 | I9: =VLOOKUP(A9,manday,34,FALSE) -> 77 | J9: =G9/I9 -> 0.80883117
B10: =SUM(B7:B9) -> 163.73 | C10: =SUM(C7:C9) -> 190.06 | D10: =SUM(D7:D9) -> 146.76 | E10: =SUM(E7:E9) -> 63.45 | F10: =SUM(F7:F9) -> 2.61 | G10: =SUM(G7:G9) -> 212.82 | I10: =SUM(I7:I9) -> 229
J12: MT per person
J13: =G10/(D3-D4) -> 21.282
J16: HA per person
J17: =B10/(D3-D4) -> 16.373
J20: Ratio HA to MT per person
J21: =J17/J17&":"&ROUND(J13/J17,2) -> 1:1.3
B24: *MIKHAEL led the gang until end of June 2025
B25: In July 2025 the report continued using MIKHAEL's name as leader of the gang.
B26: Should be have YUVENTUS UN
E55: Sept-25 vs Aug-25 Diff. (%) | H55: Sept-25 vs Aug-25 Diff. (%)
E105: Sept-25 vs Sept-24 Diff. (%) | H105: Sept-25 vs Sept-24 Diff. (%)

Sheet DARSO GANG
